/home/user/venv/lib/python3.12/site-packages/django_q/conf.py:139: UserWarning: Retry and timeout are misconfigured. Set retry larger than timeout, 
        failure to do so will cause the tasks to be retriggered before completion. 
        See https://django-q.readthedocs.io/en/latest/configure.html#retry for details.
  warn(
/home/user/venv/lib/python3.12/site-packages/django_q/conf.py:139: UserWarning: Retry and timeout are misconfigured. Set retry larger than timeout, 
        failure to do so will cause the tasks to be retriggered before completion. 
        See https://django-q.readthedocs.io/en/latest/configure.html#retry for details.
  warn(
/home/user/venv/lib/python3.12/site-packages/django_q/conf.py:139: UserWarning: Retry and timeout are misconfigured. Set retry larger than timeout, 
        failure to do so will cause the tasks to be retriggered before completion. 
        See https://django-q.readthedocs.io/en/latest/configure.html#retry for details.
  warn(
/home/user/venv/lib/python3.12/site-packages/django_q/conf.py:139: UserWarning: Retry and timeout are misconfigured. Set retry larger than timeout, 
        failure to do so will cause the tasks to be retriggered before completion. 
        See https://django-q.readthedocs.io/en/latest/configure.html#retry for details.
  warn(
12:18:14 [Q] INFO Q Cluster quiet-mars-lake-sad starting.
12:18:14 [Q] INFO Process-1:1 ready for work at 9234
12:18:14 [Q] INFO Process-1:2 monitoring at 9235
12:18:14 [Q] INFO Process-1 guarding cluster quiet-mars-lake-sad
12:18:14 [Q] INFO Process-1:3 pushing tasks at 9236
12:18:14 [Q] INFO Q Cluster quiet-mars-lake-sad running.
[31/Dec/2024 12:18:35] "GET /admin/django_q/schedule/ HTTP/1.1" 200 8848
[31/Dec/2024 12:18:35] "GET /admin/jsi18n/ HTTP/1.1" 200 3325
[31/Dec/2024 12:18:38] "GET /admin/django_q/schedule/ HTTP/1.1" 200 8848
[31/Dec/2024 12:18:38] "GET /admin/jsi18n/ HTTP/1.1" 200 3325
[31/Dec/2024 12:18:41] "GET /admin/django_q/schedule/add/ HTTP/1.1" 200 13345
[31/Dec/2024 12:18:41] "GET /static/admin/css/forms.1d89ec6432f5.css HTTP/1.1" 200 2184
[31/Dec/2024 12:18:41] "GET /admin/jsi18n/ HTTP/1.1" 200 3325
[31/Dec/2024 12:18:41] "GET /static/admin/css/widgets.694d845b2cb1.css HTTP/1.1" 200 2368
[31/Dec/2024 12:18:41] "GET /static/admin/js/calendar.f8a5d055eb33.js HTTP/1.1" 200 2193
[31/Dec/2024 12:18:41] "GET /static/admin/js/prepopulate_init.e056047b7a7e.js HTTP/1.1" 200 267
[31/Dec/2024 12:18:41] "GET /static/admin/js/admin/DateTimeShortcuts.5548f99471bf.js HTTP/1.1" 200 3729
[31/Dec/2024 12:18:41] "GET /static/admin/js/change_form.9d8ca4f96b75.js HTTP/1.1" 200 322
[31/Dec/2024 12:18:41] "GET /static/admin/img/icon-calendar.ac7aea671bea.svg HTTP/1.1" 200 438
[31/Dec/2024 12:18:41] "GET /static/admin/img/icon-clock.e1d4dfac3f2b.svg HTTP/1.1" 200 357
[31/Dec/2024 12:19:22] "GET / HTTP/1.1" 404 179
[31/Dec/2024 12:19:22] "GET /favicon.ico HTTP/1.1" 404 179
[31/Dec/2024 12:19:24] "GET / HTTP/1.1" 404 179
[31/Dec/2024 12:20:10] "POST /admin/django_q/schedule/add/ HTTP/1.1" 302 0
[31/Dec/2024 12:20:10] "GET /admin/django_q/schedule/ HTTP/1.1" 200 12219
[31/Dec/2024 12:20:10] "GET /admin/jsi18n/ HTTP/1.1" 200 3325
[31/Dec/2024 12:20:10] "GET /static/admin/img/icon-unknown.a18cb4398978.svg HTTP/1.1" 200 377
[31/Dec/2024 12:20:11] "GET /static/admin/img/icon-yes.d2f9f035226a.svg HTTP/1.1" 200 266
[31/Dec/2024 12:20:11] "GET /static/admin/img/sorting-icons.3a097b59f104.svg HTTP/1.1" 200 366
12:20:14 [Q] INFO Enqueued 1
12:20:14 [Q] INFO Process-1 created a task from schedule [sent nimadur]
12:20:14 [Q] INFO Process-1:1 processing [juliet-river-failed-oscar]
12:20:14 [Q] ERROR Failed [juliet-river-failed-oscar] - 'NoneType' object has no attribute 'message' : Traceback (most recent call last):
  File "/home/user/venv/lib/python3.12/site-packages/django_q/cluster.py", line 432, in worker
    res = f(*task["args"], **task["kwargs"])
          ^^^^^^^^^^^^^^^^^^^^^^^^^^^^^^^^^^
  File "/home/user/KepfutsiyBot/bot_notifier/tasks/send_daily_sentence.py", line 17, in send_task
    text = Sentence.objects.order_by('?').first().message
           ^^^^^^^^^^^^^^^^^^^^^^^^^^^^^^^^^^^^^^^^^^^^^^
AttributeError: 'NoneType' object has no attribute 'message'

[31/Dec/2024 12:20:32] "GET /admin/bot_notifier/sentence/ HTTP/1.1" 200 6531
[31/Dec/2024 12:20:32] "GET /admin/jsi18n/ HTTP/1.1" 200 3325
[31/Dec/2024 12:20:34] "GET /admin/bot_notifier/sentence/add/ HTTP/1.1" 200 8762
[31/Dec/2024 12:20:35] "GET /admin/jsi18n/ HTTP/1.1" 200 3325
[31/Dec/2024 12:20:39] "POST /admin/bot_notifier/sentence/add/ HTTP/1.1" 302 0
[31/Dec/2024 12:20:39] "GET /admin/bot_notifier/sentence/ HTTP/1.1" 200 7903
[31/Dec/2024 12:20:39] "GET /admin/jsi18n/ HTTP/1.1" 200 3325
12:20:44 [Q] INFO Enqueued 1
12:20:44 [Q] INFO Process-1 created a task from schedule [sent nimadur]
12:20:44 [Q] INFO Process-1:1 processing [orange-mango-utah-april]
12:20:45 [Q] INFO Processed [orange-mango-utah-april]
[31/Dec/2024 12:20:53] "GET /admin/auth/user/ HTTP/1.1" 200 9926
[31/Dec/2024 12:20:53] "GET /admin/jsi18n/ HTTP/1.1" 200 3325
[31/Dec/2024 12:20:59] "GET /admin/auth/user/ HTTP/1.1" 200 9926
[31/Dec/2024 12:20:59] "GET /admin/jsi18n/ HTTP/1.1" 200 3325
2024-12-31 12:21:02,026 (__init__.py:1115 MainThread) ERROR - TeleBot: "Infinity polling exception: duplicate key value violates unique constraint "bot_notifier_botuser_chat_id_key"
DETAIL:  Key (chat_id)=(1470843168) already exists.
"
2024-12-31 12:21:02,034 (__init__.py:1117 MainThread) ERROR - TeleBot: "Exception traceback:
Traceback (most recent call last):
  File "/home/user/venv/lib/python3.12/site-packages/django/db/backends/utils.py", line 84, in _execute
    return self.cursor.execute(sql, params)
           ^^^^^^^^^^^^^^^^^^^^^^^^^^^^^^^^
psycopg2.errors.UniqueViolation: duplicate key value violates unique constraint "bot_notifier_botuser_chat_id_key"
DETAIL:  Key (chat_id)=(1470843168) already exists.


The above exception was the direct cause of the following exception:

Traceback (most recent call last):
  File "/home/user/venv/lib/python3.12/site-packages/telebot/__init__.py", line 1110, in infinity_polling
    self.polling(non_stop=True, timeout=timeout, long_polling_timeout=long_polling_timeout,
  File "/home/user/venv/lib/python3.12/site-packages/telebot/__init__.py", line 1198, in polling
    self.__threaded_polling(non_stop=non_stop, interval=interval, timeout=timeout, long_polling_timeout=long_polling_timeout,
  File "/home/user/venv/lib/python3.12/site-packages/telebot/__init__.py", line 1273, in __threaded_polling
    raise e
  File "/home/user/venv/lib/python3.12/site-packages/telebot/__init__.py", line 1235, in __threaded_polling
    self.worker_pool.raise_exceptions()
  File "/home/user/venv/lib/python3.12/site-packages/telebot/util.py", line 150, in raise_exceptions
    raise self.exception_info
  File "/home/user/venv/lib/python3.12/site-packages/telebot/util.py", line 93, in run
    task(*args, **kwargs)
  File "/home/user/venv/lib/python3.12/site-packages/telebot/__init__.py", line 9165, in _run_middlewares_and_handler
    result = handler['function'](message)
             ^^^^^^^^^^^^^^^^^^^^^^^^^^^^
  File "/home/user/KepfutsiyBot/bot.py", line 18, in send_welcome
    BotUser.objects.create(chat_id=message.chat.id, first_name=message.chat.first_name, username=message.chat.username)
  File "/home/user/venv/lib/python3.12/site-packages/django/db/models/manager.py", line 85, in manager_method
    return getattr(self.get_queryset(), name)(*args, **kwargs)
           ^^^^^^^^^^^^^^^^^^^^^^^^^^^^^^^^^^^^^^^^^^^^^^^^^^^
  File "/home/user/venv/lib/python3.12/site-packages/django/db/models/query.py", line 453, in create
    obj.save(force_insert=True, using=self.db)
  File "/home/user/venv/lib/python3.12/site-packages/django/db/models/base.py", line 739, in save
    self.save_base(using=using, force_insert=force_insert,
  File "/home/user/venv/lib/python3.12/site-packages/django/db/models/base.py", line 776, in save_base
    updated = self._save_table(
              ^^^^^^^^^^^^^^^^^
  File "/home/user/venv/lib/python3.12/site-packages/django/db/models/base.py", line 881, in _save_table
    results = self._do_insert(cls._base_manager, using, fields, returning_fields, raw)
              ^^^^^^^^^^^^^^^^^^^^^^^^^^^^^^^^^^^^^^^^^^^^^^^^^^^^^^^^^^^^^^^^^^^^^^^^
  File "/home/user/venv/lib/python3.12/site-packages/django/db/models/base.py", line 919, in _do_insert
    return manager._insert(
           ^^^^^^^^^^^^^^^^
  File "/home/user/venv/lib/python3.12/site-packages/django/db/models/manager.py", line 85, in manager_method
    return getattr(self.get_queryset(), name)(*args, **kwargs)
           ^^^^^^^^^^^^^^^^^^^^^^^^^^^^^^^^^^^^^^^^^^^^^^^^^^^
  File "/home/user/venv/lib/python3.12/site-packages/django/db/models/query.py", line 1270, in _insert
    return query.get_compiler(using=using).execute_sql(returning_fields)
           ^^^^^^^^^^^^^^^^^^^^^^^^^^^^^^^^^^^^^^^^^^^^^^^^^^^^^^^^^^^^^
  File "/home/user/venv/lib/python3.12/site-packages/django/db/models/sql/compiler.py", line 1416, in execute_sql
    cursor.execute(sql, params)
  File "/home/user/venv/lib/python3.12/site-packages/django/db/backends/utils.py", line 66, in execute
    return self._execute_with_wrappers(sql, params, many=False, executor=self._execute)
           ^^^^^^^^^^^^^^^^^^^^^^^^^^^^^^^^^^^^^^^^^^^^^^^^^^^^^^^^^^^^^^^^^^^^^^^^^^^^
  File "/home/user/venv/lib/python3.12/site-packages/django/db/backends/utils.py", line 75, in _execute_with_wrappers
    return executor(sql, params, many, context)
           ^^^^^^^^^^^^^^^^^^^^^^^^^^^^^^^^^^^^
  File "/home/user/venv/lib/python3.12/site-packages/django/db/backends/utils.py", line 79, in _execute
    with self.db.wrap_database_errors:
  File "/home/user/venv/lib/python3.12/site-packages/django/db/utils.py", line 90, in __exit__
    raise dj_exc_value.with_traceback(traceback) from exc_value
  File "/home/user/venv/lib/python3.12/site-packages/django/db/backends/utils.py", line 84, in _execute
    return self.cursor.execute(sql, params)
           ^^^^^^^^^^^^^^^^^^^^^^^^^^^^^^^^
django.db.utils.IntegrityError: duplicate key value violates unique constraint "bot_notifier_botuser_chat_id_key"
DETAIL:  Key (chat_id)=(1470843168) already exists.

"
[31/Dec/2024 12:21:04] "GET /admin/auth/user/ HTTP/1.1" 200 9926
[31/Dec/2024 12:21:04] "GET /admin/jsi18n/ HTTP/1.1" 200 3325
[31/Dec/2024 12:21:06] "GET /admin/auth/user/1/change/ HTTP/1.1" 200 19372
[31/Dec/2024 12:21:06] "GET /static/admin/js/SelectBox.8161741c7647.js HTTP/1.1" 200 976
[31/Dec/2024 12:21:06] "GET /static/admin/js/SelectFilter2.d250dcb52a9a.js HTTP/1.1" 200 2638
[31/Dec/2024 12:21:06] "GET /admin/jsi18n/ HTTP/1.1" 200 3325
[31/Dec/2024 12:21:06] "GET /static/admin/img/icon-unknown-alt.81536e128bb6.svg HTTP/1.1" 200 377
[31/Dec/2024 12:21:06] "GET /static/admin/img/selector-icons.b4555096cea2.svg HTTP/1.1" 200 770
[31/Dec/2024 12:21:09] "GET /admin/bot_notifier/botuser/ HTTP/1.1" 200 7912
[31/Dec/2024 12:21:09] "GET /admin/jsi18n/ HTTP/1.1" 200 3325
[31/Dec/2024 12:21:11] "GET /admin/bot_notifier/sentence/ HTTP/1.1" 200 7692
[31/Dec/2024 12:21:12] "GET /admin/jsi18n/ HTTP/1.1" 200 3325
12:21:14 [Q] INFO Enqueued 1
12:21:14 [Q] INFO Process-1 created a task from schedule [sent nimadur]
12:21:14 [Q] INFO Process-1:1 processing [lithium-five-emma-texas]
12:21:15 [Q] INFO Processed [lithium-five-emma-texas]
12:21:44 [Q] INFO Enqueued 1
12:21:44 [Q] INFO Process-1 created a task from schedule [sent nimadur]
12:21:44 [Q] INFO Process-1:1 processing [chicken-stairway-whiskey-kansas]
12:21:45 [Q] INFO Processed [chicken-stairway-whiskey-kansas]
12:22:44 [Q] INFO Enqueued 1
12:22:44 [Q] INFO Process-1 created a task from schedule [sent nimadur]
12:22:44 [Q] INFO Process-1:1 processing [kentucky-mirror-colorado-bluebird]
12:22:45 [Q] INFO Processed [kentucky-mirror-colorado-bluebird]
[31/Dec/2024 12:22:56] code 400, message Bad request version ('ÍþÁaS\x07CL-l.0WJ©ËF\x03k´×Î\x00')
[31/Dec/2024 12:22:56] You're accessing the development server over HTTPS, but it only supports HTTP.

[31/Dec/2024 12:22:56] code 400, message Bad request version (',\x11ú_;49\x11nn\x99\xad\x87¢')
[31/Dec/2024 12:22:56] You're accessing the development server over HTTPS, but it only supports HTTP.

[31/Dec/2024 12:22:56] "GET /admin HTTP/1.1" 301 0
[31/Dec/2024 12:22:56] "GET /admin/ HTTP/1.1" 302 0
[31/Dec/2024 12:22:56] "GET /admin/login/?next=/admin/ HTTP/1.1" 200 2279
[31/Dec/2024 12:22:56] "GET /static/admin/css/base.1f418065fc2c.css HTTP/1.1" 200 4649
[31/Dec/2024 12:22:56] "GET /static/admin/css/nav_sidebar.0fd434145f4d.css HTTP/1.1" 200 673
[31/Dec/2024 12:22:56] "GET /static/admin/css/responsive.b128bdf0edef.css HTTP/1.1" 200 3389
[31/Dec/2024 12:22:56] "GET /static/admin/css/login.c35adf41bb6e.css HTTP/1.1" 200 410
[31/Dec/2024 12:22:56] "GET /static/admin/js/nav_sidebar.7605597ddf52.js HTTP/1.1" 200 412
[31/Dec/2024 12:22:57] "GET /static/admin/css/fonts.168bab448fee.css HTTP/1.1" 200 189
[31/Dec/2024 12:22:57] "GET /static/admin/fonts/Roboto-Regular-webfont.35b07eb2f871.woff HTTP/1.1" 200 85876
[31/Dec/2024 12:22:57] "GET /static/admin/fonts/Roboto-Light-webfont.c73eb1ceba33.woff HTTP/1.1" 200 85692
[31/Dec/2024 12:22:57] "GET /favicon.ico HTTP/1.1" 404 179
[31/Dec/2024 12:22:57] code 400, message Bad request version ('**\x13\x01\x13\x02\x13\x03À+À/À,À0Ì©Ì¨À\x13À\x14\x00\x9c\x00\x9d\x00/\x005\x01\x00\x063\x1a\x1a\x00\x00\x00')
[31/Dec/2024 12:22:57] You're accessing the development server over HTTPS, but it only supports HTTP.

[31/Dec/2024 12:22:57] code 400, message Bad request syntax ("\x16\x03\x01\x06à\x01\x00\x06Ü\x03\x03\x8d¨'!ªsXÙÁÑb7\x8aJ\x8c¼à\x08\x9a\x18")
[31/Dec/2024 12:22:57] You're accessing the development server over HTTPS, but it only supports HTTP.

[31/Dec/2024 12:23:03] code 400, message Bad request version ('ï\x8at\x823\x96Ñ\x89L7\x00Ð\x92´rì¥Bq')
[31/Dec/2024 12:23:03] You're accessing the development server over HTTPS, but it only supports HTTP.

[31/Dec/2024 12:23:03] code 400, message Bad request syntax ('\x16\x03\x01\x06À\x01\x00\x06¼\x03\x030bm\x81ùÍ\x16Ò¿µpñÓ\x15´A\x9b"\x0f]æ\x82ùX\x9aç\x9eeé')
[31/Dec/2024 12:23:03] You're accessing the development server over HTTPS, but it only supports HTTP.

[31/Dec/2024 12:23:03] "POST /admin/login/?next=/admin/ HTTP/1.1" 302 0
[31/Dec/2024 12:23:03] "GET /admin/ HTTP/1.1" 200 6631
[31/Dec/2024 12:23:03] "GET /static/admin/css/dashboard.be83f13e4369.css HTTP/1.1" 200 245
[31/Dec/2024 12:23:04] "GET /static/admin/img/icon-addlink.d519b3bab011.svg HTTP/1.1" 200 206
[31/Dec/2024 12:23:04] "GET /static/admin/img/icon-changelink.18d2fd706348.svg HTTP/1.1" 200 269
[31/Dec/2024 12:23:04] "GET /static/admin/fonts/Roboto-Bold-webfont.50d75e48e0a3.woff HTTP/1.1" 200 86184
[31/Dec/2024 12:23:06] "GET /admin/bot_notifier/sentence/ HTTP/1.1" 200 7692
[31/Dec/2024 12:23:06] "GET /static/admin/css/changelists.c70d77c47e69.css HTTP/1.1" 200 1566
[31/Dec/2024 12:23:06] "GET /static/admin/js/vendor/jquery/jquery.min.dc5e7f18c8d3.js HTTP/1.1" 200 30879
[31/Dec/2024 12:23:06] "GET /static/admin/js/core.ccd84108ec57.js HTTP/1.1" 200 1505
[31/Dec/2024 12:23:06] "GET /static/admin/js/jquery.init.b7781a0897fc.js HTTP/1.1" 200 236
[31/Dec/2024 12:23:06] "GET /static/admin/js/admin/RelatedObjectLookups.b4d76b6aaf0b.js HTTP/1.1" 200 1571
[31/Dec/2024 12:23:06] "GET /admin/jsi18n/ HTTP/1.1" 200 3325
[31/Dec/2024 12:23:06] "GET /static/admin/js/actions.3edba334d0a4.js HTTP/1.1" 200 1874
[31/Dec/2024 12:23:06] "GET /static/admin/js/urlify.25cc3eac8123.js HTTP/1.1" 200 2581
[31/Dec/2024 12:23:06] "GET /static/admin/js/prepopulate.bd2361dfd64d.js HTTP/1.1" 200 536
[31/Dec/2024 12:23:06] "GET /static/admin/js/vendor/xregexp/xregexp.min.b0439563a5d3.js HTTP/1.1" 200 37609
[31/Dec/2024 12:23:07] "GET /static/admin/img/tooltag-add.e59d620a9742.svg HTTP/1.1" 200 203
[31/Dec/2024 12:23:08] "GET /admin/bot_notifier/sentence/1/change/ HTTP/1.1" 200 9027
[31/Dec/2024 12:23:08] "GET /static/admin/css/forms.1d89ec6432f5.css HTTP/1.1" 200 2184
[31/Dec/2024 12:23:08] "GET /static/admin/js/calendar.f8a5d055eb33.js HTTP/1.1" 200 2193
[31/Dec/2024 12:23:08] "GET /static/admin/js/admin/DateTimeShortcuts.5548f99471bf.js HTTP/1.1" 200 3729
[31/Dec/2024 12:23:08] "GET /static/admin/js/prepopulate_init.e056047b7a7e.js HTTP/1.1" 200 267
[31/Dec/2024 12:23:08] "GET /admin/jsi18n/ HTTP/1.1" 200 3325
[31/Dec/2024 12:23:08] "GET /static/admin/css/widgets.694d845b2cb1.css HTTP/1.1" 200 2368
[31/Dec/2024 12:23:08] "GET /static/admin/js/change_form.9d8ca4f96b75.js HTTP/1.1" 200 322
[31/Dec/2024 12:23:08] "GET /static/admin/img/icon-calendar.ac7aea671bea.svg HTTP/1.1" 200 438
[31/Dec/2024 12:23:08] "GET /static/admin/img/icon-clock.e1d4dfac3f2b.svg HTTP/1.1" 200 357
12:23:45 [Q] INFO Enqueued 1
12:23:45 [Q] INFO Process-1 created a task from schedule [sent nimadur]
12:23:45 [Q] INFO Process-1:1 processing [kilo-pluto-sixteen-fix]
12:23:45 [Q] INFO Processed [kilo-pluto-sixteen-fix]
[31/Dec/2024 12:23:48] "GET /admin/bot_notifier/sentence/ HTTP/1.1" 200 7692
[31/Dec/2024 12:23:48] "GET /admin/jsi18n/ HTTP/1.1" 200 3325
[31/Dec/2024 12:24:12] "GET /admin/django_q/failure/ HTTP/1.1" 200 9584
[31/Dec/2024 12:24:12] "GET /admin/jsi18n/ HTTP/1.1" 200 3325
[31/Dec/2024 12:24:16] "GET /admin/django_q/schedule/ HTTP/1.1" 200 12065
[31/Dec/2024 12:24:16] "GET /admin/jsi18n/ HTTP/1.1" 200 3325
[31/Dec/2024 12:24:18] "GET /admin/django_q/schedule/1/change/ HTTP/1.1" 200 13782
[31/Dec/2024 12:24:18] "GET /admin/jsi18n/ HTTP/1.1" 200 3325
[31/Dec/2024 12:24:26] "POST /admin/django_q/schedule/1/change/ HTTP/1.1" 302 0
[31/Dec/2024 12:24:26] "GET /admin/django_q/schedule/ HTTP/1.1" 200 12317
[31/Dec/2024 12:24:26] "GET /admin/jsi18n/ HTTP/1.1" 200 3325
[31/Dec/2024 12:24:42] "POST /admin/bot_notifier/sentence/1/change/ HTTP/1.1" 302 0
[31/Dec/2024 12:24:43] "GET /admin/bot_notifier/sentence/ HTTP/1.1" 200 8085
[31/Dec/2024 12:24:43] "GET /admin/jsi18n/ HTTP/1.1" 200 3325
[31/Dec/2024 12:24:43] "GET /static/admin/img/icon-yes.d2f9f035226a.svg HTTP/1.1" 200 266
[31/Dec/2024 12:24:44] "GET /admin/bot_notifier/sentence/1/change/ HTTP/1.1" 200 9387
[31/Dec/2024 12:24:44] "GET /admin/jsi18n/ HTTP/1.1" 200 3325
12:24:45 [Q] INFO Enqueued 1
12:24:45 [Q] INFO Process-1 created a task from schedule [sent nimadur]
12:24:45 [Q] INFO Process-1:1 processing [colorado-snake-missouri-louisiana]
12:24:46 [Q] INFO Processed [colorado-snake-missouri-louisiana]
[31/Dec/2024 12:24:58] "GET /admin/bot_notifier/sentence/ HTTP/1.1" 200 7782
[31/Dec/2024 12:24:58] "GET /admin/jsi18n/ HTTP/1.1" 200 3325
[31/Dec/2024 12:25:00] "GET /admin/bot_notifier/ HTTP/1.1" 200 3332
[31/Dec/2024 12:25:55] "GET /admin/django_q/schedule/ HTTP/1.1" 200 12073
[31/Dec/2024 12:25:56] "GET /admin/jsi18n/ HTTP/1.1" 200 3325
[31/Dec/2024 12:26:19] "GET /admin/django_q/schedule/ HTTP/1.1" 200 12073
[31/Dec/2024 12:26:19] "GET /admin/jsi18n/ HTTP/1.1" 200 3325
[31/Dec/2024 12:26:23] "GET /admin/bot_notifier/botuser/ HTTP/1.1" 200 8129
[31/Dec/2024 12:26:23] "GET /admin/jsi18n/ HTTP/1.1" 200 3325
[31/Dec/2024 12:27:07] "GET /admin/auth/user/ HTTP/1.1" 200 9926
[31/Dec/2024 12:27:08] "GET /admin/jsi18n/ HTTP/1.1" 200 3325
[31/Dec/2024 12:27:16] "GET /admin/auth/user/ HTTP/1.1" 200 9926
[31/Dec/2024 12:27:17] "GET /admin/jsi18n/ HTTP/1.1" 200 3325
[31/Dec/2024 12:27:20] "GET /admin/bot_notifier/sentence/ HTTP/1.1" 200 7782
[31/Dec/2024 12:27:20] "GET /admin/jsi18n/ HTTP/1.1" 200 3325
[31/Dec/2024 12:27:27] "GET /admin/django_q/failure/ HTTP/1.1" 200 9584
[31/Dec/2024 12:27:27] "GET /admin/jsi18n/ HTTP/1.1" 200 3325
[31/Dec/2024 12:27:29] "GET /admin/django_q/schedule/ HTTP/1.1" 200 12073
[31/Dec/2024 12:27:29] "GET /admin/jsi18n/ HTTP/1.1" 200 3325
[31/Dec/2024 12:27:34] "GET /admin/django_q/success/ HTTP/1.1" 200 12472
[31/Dec/2024 12:27:34] "GET /admin/jsi18n/ HTTP/1.1" 200 3325
[31/Dec/2024 12:28:42] "GET /admin/bot_notifier/botuser/ HTTP/1.1" 200 8129
[31/Dec/2024 12:28:43] "GET /admin/jsi18n/ HTTP/1.1" 200 3325
[31/Dec/2024 14:39:18] "GET /admin/bot_notifier/botuser/ HTTP/1.1" 200 8129
[31/Dec/2024 14:39:19] "GET /favicon.ico HTTP/1.1" 404 179
[31/Dec/2024 17:18:47] "GET /admin/bot_notifier/botuser/ HTTP/1.1" 200 8129
[31/Dec/2024 17:18:48] "GET /favicon.ico HTTP/1.1" 404 179
2024-12-31 18:13:49,024 (__init__.py:1115 MainThread) ERROR - TeleBot: "Infinity polling exception: duplicate key value violates unique constraint "bot_notifier_botuser_chat_id_key"
DETAIL:  Key (chat_id)=(5840353287) already exists.
"
2024-12-31 18:13:49,026 (__init__.py:1117 MainThread) ERROR - TeleBot: "Exception traceback:
Traceback (most recent call last):
  File "/home/user/venv/lib/python3.12/site-packages/django/db/backends/utils.py", line 84, in _execute
    return self.cursor.execute(sql, params)
           ^^^^^^^^^^^^^^^^^^^^^^^^^^^^^^^^
psycopg2.errors.UniqueViolation: duplicate key value violates unique constraint "bot_notifier_botuser_chat_id_key"
DETAIL:  Key (chat_id)=(5840353287) already exists.


The above exception was the direct cause of the following exception:

Traceback (most recent call last):
  File "/home/user/venv/lib/python3.12/site-packages/telebot/__init__.py", line 1110, in infinity_polling
    self.polling(non_stop=True, timeout=timeout, long_polling_timeout=long_polling_timeout,
  File "/home/user/venv/lib/python3.12/site-packages/telebot/__init__.py", line 1198, in polling
    self.__threaded_polling(non_stop=non_stop, interval=interval, timeout=timeout, long_polling_timeout=long_polling_timeout,
  File "/home/user/venv/lib/python3.12/site-packages/telebot/__init__.py", line 1273, in __threaded_polling
    raise e
  File "/home/user/venv/lib/python3.12/site-packages/telebot/__init__.py", line 1235, in __threaded_polling
    self.worker_pool.raise_exceptions()
  File "/home/user/venv/lib/python3.12/site-packages/telebot/util.py", line 150, in raise_exceptions
    raise self.exception_info
  File "/home/user/venv/lib/python3.12/site-packages/telebot/util.py", line 93, in run
    task(*args, **kwargs)
  File "/home/user/venv/lib/python3.12/site-packages/telebot/__init__.py", line 9165, in _run_middlewares_and_handler
    result = handler['function'](message)
             ^^^^^^^^^^^^^^^^^^^^^^^^^^^^
  File "/home/user/KepfutsiyBot/bot.py", line 18, in send_welcome
    BotUser.objects.create(chat_id=message.chat.id, first_name=message.chat.first_name, username=message.chat.username)
  File "/home/user/venv/lib/python3.12/site-packages/django/db/models/manager.py", line 85, in manager_method
    return getattr(self.get_queryset(), name)(*args, **kwargs)
           ^^^^^^^^^^^^^^^^^^^^^^^^^^^^^^^^^^^^^^^^^^^^^^^^^^^
  File "/home/user/venv/lib/python3.12/site-packages/django/db/models/query.py", line 453, in create
    obj.save(force_insert=True, using=self.db)
  File "/home/user/venv/lib/python3.12/site-packages/django/db/models/base.py", line 739, in save
    self.save_base(using=using, force_insert=force_insert,
  File "/home/user/venv/lib/python3.12/site-packages/django/db/models/base.py", line 776, in save_base
    updated = self._save_table(
              ^^^^^^^^^^^^^^^^^
  File "/home/user/venv/lib/python3.12/site-packages/django/db/models/base.py", line 881, in _save_table
    results = self._do_insert(cls._base_manager, using, fields, returning_fields, raw)
              ^^^^^^^^^^^^^^^^^^^^^^^^^^^^^^^^^^^^^^^^^^^^^^^^^^^^^^^^^^^^^^^^^^^^^^^^
  File "/home/user/venv/lib/python3.12/site-packages/django/db/models/base.py", line 919, in _do_insert
    return manager._insert(
           ^^^^^^^^^^^^^^^^
  File "/home/user/venv/lib/python3.12/site-packages/django/db/models/manager.py", line 85, in manager_method
    return getattr(self.get_queryset(), name)(*args, **kwargs)
           ^^^^^^^^^^^^^^^^^^^^^^^^^^^^^^^^^^^^^^^^^^^^^^^^^^^
  File "/home/user/venv/lib/python3.12/site-packages/django/db/models/query.py", line 1270, in _insert
    return query.get_compiler(using=using).execute_sql(returning_fields)
           ^^^^^^^^^^^^^^^^^^^^^^^^^^^^^^^^^^^^^^^^^^^^^^^^^^^^^^^^^^^^^
  File "/home/user/venv/lib/python3.12/site-packages/django/db/models/sql/compiler.py", line 1416, in execute_sql
    cursor.execute(sql, params)
  File "/home/user/venv/lib/python3.12/site-packages/django/db/backends/utils.py", line 66, in execute
    return self._execute_with_wrappers(sql, params, many=False, executor=self._execute)
           ^^^^^^^^^^^^^^^^^^^^^^^^^^^^^^^^^^^^^^^^^^^^^^^^^^^^^^^^^^^^^^^^^^^^^^^^^^^^
  File "/home/user/venv/lib/python3.12/site-packages/django/db/backends/utils.py", line 75, in _execute_with_wrappers
    return executor(sql, params, many, context)
           ^^^^^^^^^^^^^^^^^^^^^^^^^^^^^^^^^^^^
  File "/home/user/venv/lib/python3.12/site-packages/django/db/backends/utils.py", line 79, in _execute
    with self.db.wrap_database_errors:
  File "/home/user/venv/lib/python3.12/site-packages/django/db/utils.py", line 90, in __exit__
    raise dj_exc_value.with_traceback(traceback) from exc_value
  File "/home/user/venv/lib/python3.12/site-packages/django/db/backends/utils.py", line 84, in _execute
    return self.cursor.execute(sql, params)
           ^^^^^^^^^^^^^^^^^^^^^^^^^^^^^^^^
django.db.utils.IntegrityError: duplicate key value violates unique constraint "bot_notifier_botuser_chat_id_key"
DETAIL:  Key (chat_id)=(5840353287) already exists.

"
2024-12-31 19:02:18,480 (__init__.py:1115 MainThread) ERROR - TeleBot: "Infinity polling exception: HTTPSConnectionPool(host='api.telegram.org', port=443): Read timed out. (read timeout=25)"
2024-12-31 19:02:18,483 (__init__.py:1117 MainThread) ERROR - TeleBot: "Exception traceback:
Traceback (most recent call last):
  File "/home/user/venv/lib/python3.12/site-packages/urllib3/connectionpool.py", line 534, in _make_request
    response = conn.getresponse()
               ^^^^^^^^^^^^^^^^^^
  File "/home/user/venv/lib/python3.12/site-packages/urllib3/connection.py", line 516, in getresponse
    httplib_response = super().getresponse()
                       ^^^^^^^^^^^^^^^^^^^^^
  File "/usr/lib/python3.12/http/client.py", line 1428, in getresponse
    response.begin()
  File "/usr/lib/python3.12/http/client.py", line 331, in begin
    version, status, reason = self._read_status()
                              ^^^^^^^^^^^^^^^^^^^
  File "/usr/lib/python3.12/http/client.py", line 292, in _read_status
    line = str(self.fp.readline(_MAXLINE + 1), "iso-8859-1")
               ^^^^^^^^^^^^^^^^^^^^^^^^^^^^^^
  File "/usr/lib/python3.12/socket.py", line 707, in readinto
    return self._sock.recv_into(b)
           ^^^^^^^^^^^^^^^^^^^^^^^
  File "/usr/lib/python3.12/ssl.py", line 1252, in recv_into
    return self.read(nbytes, buffer)
           ^^^^^^^^^^^^^^^^^^^^^^^^^
  File "/usr/lib/python3.12/ssl.py", line 1104, in read
    return self._sslobj.read(len, buffer)
           ^^^^^^^^^^^^^^^^^^^^^^^^^^^^^^
TimeoutError: The read operation timed out

The above exception was the direct cause of the following exception:

Traceback (most recent call last):
  File "/home/user/venv/lib/python3.12/site-packages/requests/adapters.py", line 667, in send
    resp = conn.urlopen(
           ^^^^^^^^^^^^^
  File "/home/user/venv/lib/python3.12/site-packages/urllib3/connectionpool.py", line 841, in urlopen
    retries = retries.increment(
              ^^^^^^^^^^^^^^^^^^
  File "/home/user/venv/lib/python3.12/site-packages/urllib3/util/retry.py", line 474, in increment
    raise reraise(type(error), error, _stacktrace)
          ^^^^^^^^^^^^^^^^^^^^^^^^^^^^^^^^^^^^^^^^
  File "/home/user/venv/lib/python3.12/site-packages/urllib3/util/util.py", line 39, in reraise
    raise value
  File "/home/user/venv/lib/python3.12/site-packages/urllib3/connectionpool.py", line 787, in urlopen
    response = self._make_request(
               ^^^^^^^^^^^^^^^^^^^
  File "/home/user/venv/lib/python3.12/site-packages/urllib3/connectionpool.py", line 536, in _make_request
    self._raise_timeout(err=e, url=url, timeout_value=read_timeout)
  File "/home/user/venv/lib/python3.12/site-packages/urllib3/connectionpool.py", line 367, in _raise_timeout
    raise ReadTimeoutError(
urllib3.exceptions.ReadTimeoutError: HTTPSConnectionPool(host='api.telegram.org', port=443): Read timed out. (read timeout=25)

During handling of the above exception, another exception occurred:

Traceback (most recent call last):
  File "/home/user/venv/lib/python3.12/site-packages/telebot/__init__.py", line 1110, in infinity_polling
    self.polling(non_stop=True, timeout=timeout, long_polling_timeout=long_polling_timeout,
  File "/home/user/venv/lib/python3.12/site-packages/telebot/__init__.py", line 1198, in polling
    self.__threaded_polling(non_stop=non_stop, interval=interval, timeout=timeout, long_polling_timeout=long_polling_timeout,
  File "/home/user/venv/lib/python3.12/site-packages/telebot/__init__.py", line 1273, in __threaded_polling
    raise e
  File "/home/user/venv/lib/python3.12/site-packages/telebot/__init__.py", line 1234, in __threaded_polling
    polling_thread.raise_exceptions()
  File "/home/user/venv/lib/python3.12/site-packages/telebot/util.py", line 111, in raise_exceptions
    raise self.exception_info
  File "/home/user/venv/lib/python3.12/site-packages/telebot/util.py", line 93, in run
    task(*args, **kwargs)
  File "/home/user/venv/lib/python3.12/site-packages/telebot/__init__.py", line 688, in __retrieve_updates
    updates = self.get_updates(offset=(self.last_update_id + 1),
             ^^^^^^^^^^^^^^^^^^^^^^^^^^^^^^^^^^^^^^^^^^^^^^^^^^
  File "/home/user/venv/lib/python3.12/site-packages/telebot/__init__.py", line 660, in get_updates
    json_updates = apihelper.get_updates(
                   ^^^^^^^^^^^^^^^^^^^^^^
  File "/home/user/venv/lib/python3.12/site-packages/telebot/apihelper.py", line 332, in get_updates
    return _make_request(token, method_url, params=payload)
           ^^^^^^^^^^^^^^^^^^^^^^^^^^^^^^^^^^^^^^^^^^^^^^^^
  File "/home/user/venv/lib/python3.12/site-packages/telebot/apihelper.py", line 162, in _make_request
    result = _get_req_session().request(
             ^^^^^^^^^^^^^^^^^^^^^^^^^^^
  File "/home/user/venv/lib/python3.12/site-packages/requests/sessions.py", line 589, in request
    resp = self.send(prep, **send_kwargs)
           ^^^^^^^^^^^^^^^^^^^^^^^^^^^^^^
  File "/home/user/venv/lib/python3.12/site-packages/requests/sessions.py", line 703, in send
    r = adapter.send(request, **kwargs)
        ^^^^^^^^^^^^^^^^^^^^^^^^^^^^^^^
  File "/home/user/venv/lib/python3.12/site-packages/requests/adapters.py", line 713, in send
    raise ReadTimeout(e, request=request)
requests.exceptions.ReadTimeout: HTTPSConnectionPool(host='api.telegram.org', port=443): Read timed out. (read timeout=25)
"
2024-12-31 19:06:52,135 (__init__.py:1115 MainThread) ERROR - TeleBot: "Infinity polling exception: HTTPSConnectionPool(host='api.telegram.org', port=443): Read timed out. (read timeout=25)"
2024-12-31 19:06:52,138 (__init__.py:1117 MainThread) ERROR - TeleBot: "Exception traceback:
Traceback (most recent call last):
  File "/home/user/venv/lib/python3.12/site-packages/urllib3/connectionpool.py", line 534, in _make_request
    response = conn.getresponse()
               ^^^^^^^^^^^^^^^^^^
  File "/home/user/venv/lib/python3.12/site-packages/urllib3/connection.py", line 516, in getresponse
    httplib_response = super().getresponse()
                       ^^^^^^^^^^^^^^^^^^^^^
  File "/usr/lib/python3.12/http/client.py", line 1428, in getresponse
    response.begin()
  File "/usr/lib/python3.12/http/client.py", line 331, in begin
    version, status, reason = self._read_status()
                              ^^^^^^^^^^^^^^^^^^^
  File "/usr/lib/python3.12/http/client.py", line 292, in _read_status
    line = str(self.fp.readline(_MAXLINE + 1), "iso-8859-1")
               ^^^^^^^^^^^^^^^^^^^^^^^^^^^^^^
  File "/usr/lib/python3.12/socket.py", line 707, in readinto
    return self._sock.recv_into(b)
           ^^^^^^^^^^^^^^^^^^^^^^^
  File "/usr/lib/python3.12/ssl.py", line 1252, in recv_into
    return self.read(nbytes, buffer)
           ^^^^^^^^^^^^^^^^^^^^^^^^^
  File "/usr/lib/python3.12/ssl.py", line 1104, in read
    return self._sslobj.read(len, buffer)
           ^^^^^^^^^^^^^^^^^^^^^^^^^^^^^^
TimeoutError: The read operation timed out

The above exception was the direct cause of the following exception:

Traceback (most recent call last):
  File "/home/user/venv/lib/python3.12/site-packages/requests/adapters.py", line 667, in send
    resp = conn.urlopen(
           ^^^^^^^^^^^^^
  File "/home/user/venv/lib/python3.12/site-packages/urllib3/connectionpool.py", line 841, in urlopen
    retries = retries.increment(
              ^^^^^^^^^^^^^^^^^^
  File "/home/user/venv/lib/python3.12/site-packages/urllib3/util/retry.py", line 474, in increment
    raise reraise(type(error), error, _stacktrace)
          ^^^^^^^^^^^^^^^^^^^^^^^^^^^^^^^^^^^^^^^^
  File "/home/user/venv/lib/python3.12/site-packages/urllib3/util/util.py", line 39, in reraise
    raise value
  File "/home/user/venv/lib/python3.12/site-packages/urllib3/connectionpool.py", line 787, in urlopen
    response = self._make_request(
               ^^^^^^^^^^^^^^^^^^^
  File "/home/user/venv/lib/python3.12/site-packages/urllib3/connectionpool.py", line 536, in _make_request
    self._raise_timeout(err=e, url=url, timeout_value=read_timeout)
  File "/home/user/venv/lib/python3.12/site-packages/urllib3/connectionpool.py", line 367, in _raise_timeout
    raise ReadTimeoutError(
urllib3.exceptions.ReadTimeoutError: HTTPSConnectionPool(host='api.telegram.org', port=443): Read timed out. (read timeout=25)

During handling of the above exception, another exception occurred:

Traceback (most recent call last):
  File "/home/user/venv/lib/python3.12/site-packages/telebot/__init__.py", line 1110, in infinity_polling
    self.polling(non_stop=True, timeout=timeout, long_polling_timeout=long_polling_timeout,
  File "/home/user/venv/lib/python3.12/site-packages/telebot/__init__.py", line 1198, in polling
    self.__threaded_polling(non_stop=non_stop, interval=interval, timeout=timeout, long_polling_timeout=long_polling_timeout,
  File "/home/user/venv/lib/python3.12/site-packages/telebot/__init__.py", line 1273, in __threaded_polling
    raise e
  File "/home/user/venv/lib/python3.12/site-packages/telebot/__init__.py", line 1234, in __threaded_polling
    polling_thread.raise_exceptions()
  File "/home/user/venv/lib/python3.12/site-packages/telebot/util.py", line 111, in raise_exceptions
    raise self.exception_info
  File "/home/user/venv/lib/python3.12/site-packages/telebot/util.py", line 93, in run
    task(*args, **kwargs)
  File "/home/user/venv/lib/python3.12/site-packages/telebot/__init__.py", line 688, in __retrieve_updates
    updates = self.get_updates(offset=(self.last_update_id + 1),
             ^^^^^^^^^^^^^^^^^^^^^^^^^^^^^^^^^^^^^^^^^^^^^^^^^^
  File "/home/user/venv/lib/python3.12/site-packages/telebot/__init__.py", line 660, in get_updates
    json_updates = apihelper.get_updates(
                   ^^^^^^^^^^^^^^^^^^^^^^
  File "/home/user/venv/lib/python3.12/site-packages/telebot/apihelper.py", line 332, in get_updates
    return _make_request(token, method_url, params=payload)
           ^^^^^^^^^^^^^^^^^^^^^^^^^^^^^^^^^^^^^^^^^^^^^^^^
  File "/home/user/venv/lib/python3.12/site-packages/telebot/apihelper.py", line 162, in _make_request
    result = _get_req_session().request(
             ^^^^^^^^^^^^^^^^^^^^^^^^^^^
  File "/home/user/venv/lib/python3.12/site-packages/requests/sessions.py", line 589, in request
    resp = self.send(prep, **send_kwargs)
           ^^^^^^^^^^^^^^^^^^^^^^^^^^^^^^
  File "/home/user/venv/lib/python3.12/site-packages/requests/sessions.py", line 703, in send
    r = adapter.send(request, **kwargs)
        ^^^^^^^^^^^^^^^^^^^^^^^^^^^^^^^
  File "/home/user/venv/lib/python3.12/site-packages/requests/adapters.py", line 713, in send
    raise ReadTimeout(e, request=request)
requests.exceptions.ReadTimeout: HTTPSConnectionPool(host='api.telegram.org', port=443): Read timed out. (read timeout=25)
"
2024-12-31 19:07:16,658 (__init__.py:1241 MainThread) ERROR - TeleBot: "Threaded polling exception: A request to the Telegram API was unsuccessful. Error code: 409. Description: Conflict: terminated by other getUpdates request; make sure that only one bot instance is running"
2024-12-31 19:07:16,658 (__init__.py:1243 MainThread) ERROR - TeleBot: "Exception traceback:
Traceback (most recent call last):
  File "/home/user/venv/lib/python3.12/site-packages/telebot/__init__.py", line 1234, in __threaded_polling
    polling_thread.raise_exceptions()
  File "/home/user/venv/lib/python3.12/site-packages/telebot/util.py", line 111, in raise_exceptions
    raise self.exception_info
  File "/home/user/venv/lib/python3.12/site-packages/telebot/util.py", line 93, in run
    task(*args, **kwargs)
  File "/home/user/venv/lib/python3.12/site-packages/telebot/__init__.py", line 688, in __retrieve_updates
    updates = self.get_updates(offset=(self.last_update_id + 1),
             ^^^^^^^^^^^^^^^^^^^^^^^^^^^^^^^^^^^^^^^^^^^^^^^^^^
  File "/home/user/venv/lib/python3.12/site-packages/telebot/__init__.py", line 660, in get_updates
    json_updates = apihelper.get_updates(
                   ^^^^^^^^^^^^^^^^^^^^^^
  File "/home/user/venv/lib/python3.12/site-packages/telebot/apihelper.py", line 332, in get_updates
    return _make_request(token, method_url, params=payload)
           ^^^^^^^^^^^^^^^^^^^^^^^^^^^^^^^^^^^^^^^^^^^^^^^^
  File "/home/user/venv/lib/python3.12/site-packages/telebot/apihelper.py", line 168, in _make_request
    json_result = _check_result(method_name, result)
                  ^^^^^^^^^^^^^^^^^^^^^^^^^^^^^^^^^^
  File "/home/user/venv/lib/python3.12/site-packages/telebot/apihelper.py", line 195, in _check_result
    raise ApiTelegramException(method_name, result, result_json)
telebot.apihelper.ApiTelegramException: A request to the Telegram API was unsuccessful. Error code: 409. Description: Conflict: terminated by other getUpdates request; make sure that only one bot instance is running
"
2024-12-31 19:09:02,615 (__init__.py:1115 MainThread) ERROR - TeleBot: "Infinity polling exception: HTTPSConnectionPool(host='api.telegram.org', port=443): Read timed out. (read timeout=25)"
2024-12-31 19:09:02,618 (__init__.py:1117 MainThread) ERROR - TeleBot: "Exception traceback:
Traceback (most recent call last):
  File "/home/user/venv/lib/python3.12/site-packages/urllib3/connectionpool.py", line 534, in _make_request
    response = conn.getresponse()
               ^^^^^^^^^^^^^^^^^^
  File "/home/user/venv/lib/python3.12/site-packages/urllib3/connection.py", line 516, in getresponse
    httplib_response = super().getresponse()
                       ^^^^^^^^^^^^^^^^^^^^^
  File "/usr/lib/python3.12/http/client.py", line 1428, in getresponse
    response.begin()
  File "/usr/lib/python3.12/http/client.py", line 331, in begin
    version, status, reason = self._read_status()
                              ^^^^^^^^^^^^^^^^^^^
  File "/usr/lib/python3.12/http/client.py", line 292, in _read_status
    line = str(self.fp.readline(_MAXLINE + 1), "iso-8859-1")
               ^^^^^^^^^^^^^^^^^^^^^^^^^^^^^^
  File "/usr/lib/python3.12/socket.py", line 707, in readinto
    return self._sock.recv_into(b)
           ^^^^^^^^^^^^^^^^^^^^^^^
  File "/usr/lib/python3.12/ssl.py", line 1252, in recv_into
    return self.read(nbytes, buffer)
           ^^^^^^^^^^^^^^^^^^^^^^^^^
  File "/usr/lib/python3.12/ssl.py", line 1104, in read
    return self._sslobj.read(len, buffer)
           ^^^^^^^^^^^^^^^^^^^^^^^^^^^^^^
TimeoutError: The read operation timed out

The above exception was the direct cause of the following exception:

Traceback (most recent call last):
  File "/home/user/venv/lib/python3.12/site-packages/requests/adapters.py", line 667, in send
    resp = conn.urlopen(
           ^^^^^^^^^^^^^
  File "/home/user/venv/lib/python3.12/site-packages/urllib3/connectionpool.py", line 841, in urlopen
    retries = retries.increment(
              ^^^^^^^^^^^^^^^^^^
  File "/home/user/venv/lib/python3.12/site-packages/urllib3/util/retry.py", line 474, in increment
    raise reraise(type(error), error, _stacktrace)
          ^^^^^^^^^^^^^^^^^^^^^^^^^^^^^^^^^^^^^^^^
  File "/home/user/venv/lib/python3.12/site-packages/urllib3/util/util.py", line 39, in reraise
    raise value
  File "/home/user/venv/lib/python3.12/site-packages/urllib3/connectionpool.py", line 787, in urlopen
    response = self._make_request(
               ^^^^^^^^^^^^^^^^^^^
  File "/home/user/venv/lib/python3.12/site-packages/urllib3/connectionpool.py", line 536, in _make_request
    self._raise_timeout(err=e, url=url, timeout_value=read_timeout)
  File "/home/user/venv/lib/python3.12/site-packages/urllib3/connectionpool.py", line 367, in _raise_timeout
    raise ReadTimeoutError(
urllib3.exceptions.ReadTimeoutError: HTTPSConnectionPool(host='api.telegram.org', port=443): Read timed out. (read timeout=25)

During handling of the above exception, another exception occurred:

Traceback (most recent call last):
  File "/home/user/venv/lib/python3.12/site-packages/telebot/__init__.py", line 1110, in infinity_polling
    self.polling(non_stop=True, timeout=timeout, long_polling_timeout=long_polling_timeout,
  File "/home/user/venv/lib/python3.12/site-packages/telebot/__init__.py", line 1198, in polling
    self.__threaded_polling(non_stop=non_stop, interval=interval, timeout=timeout, long_polling_timeout=long_polling_timeout,
  File "/home/user/venv/lib/python3.12/site-packages/telebot/__init__.py", line 1273, in __threaded_polling
    raise e
  File "/home/user/venv/lib/python3.12/site-packages/telebot/__init__.py", line 1234, in __threaded_polling
    polling_thread.raise_exceptions()
  File "/home/user/venv/lib/python3.12/site-packages/telebot/util.py", line 111, in raise_exceptions
    raise self.exception_info
  File "/home/user/venv/lib/python3.12/site-packages/telebot/util.py", line 93, in run
    task(*args, **kwargs)
  File "/home/user/venv/lib/python3.12/site-packages/telebot/__init__.py", line 688, in __retrieve_updates
    updates = self.get_updates(offset=(self.last_update_id + 1),
             ^^^^^^^^^^^^^^^^^^^^^^^^^^^^^^^^^^^^^^^^^^^^^^^^^^
  File "/home/user/venv/lib/python3.12/site-packages/telebot/__init__.py", line 660, in get_updates
    json_updates = apihelper.get_updates(
                   ^^^^^^^^^^^^^^^^^^^^^^
  File "/home/user/venv/lib/python3.12/site-packages/telebot/apihelper.py", line 332, in get_updates
    return _make_request(token, method_url, params=payload)
           ^^^^^^^^^^^^^^^^^^^^^^^^^^^^^^^^^^^^^^^^^^^^^^^^
  File "/home/user/venv/lib/python3.12/site-packages/telebot/apihelper.py", line 162, in _make_request
    result = _get_req_session().request(
             ^^^^^^^^^^^^^^^^^^^^^^^^^^^
  File "/home/user/venv/lib/python3.12/site-packages/requests/sessions.py", line 589, in request
    resp = self.send(prep, **send_kwargs)
           ^^^^^^^^^^^^^^^^^^^^^^^^^^^^^^
  File "/home/user/venv/lib/python3.12/site-packages/requests/sessions.py", line 703, in send
    r = adapter.send(request, **kwargs)
        ^^^^^^^^^^^^^^^^^^^^^^^^^^^^^^^
  File "/home/user/venv/lib/python3.12/site-packages/requests/adapters.py", line 713, in send
    raise ReadTimeout(e, request=request)
requests.exceptions.ReadTimeout: HTTPSConnectionPool(host='api.telegram.org', port=443): Read timed out. (read timeout=25)
"
2024-12-31 19:17:32,134 (__init__.py:1115 MainThread) ERROR - TeleBot: "Infinity polling exception: HTTPSConnectionPool(host='api.telegram.org', port=443): Read timed out. (read timeout=25)"
2024-12-31 19:17:32,137 (__init__.py:1117 MainThread) ERROR - TeleBot: "Exception traceback:
Traceback (most recent call last):
  File "/home/user/venv/lib/python3.12/site-packages/urllib3/connectionpool.py", line 534, in _make_request
    response = conn.getresponse()
               ^^^^^^^^^^^^^^^^^^
  File "/home/user/venv/lib/python3.12/site-packages/urllib3/connection.py", line 516, in getresponse
    httplib_response = super().getresponse()
                       ^^^^^^^^^^^^^^^^^^^^^
  File "/usr/lib/python3.12/http/client.py", line 1428, in getresponse
    response.begin()
  File "/usr/lib/python3.12/http/client.py", line 331, in begin
    version, status, reason = self._read_status()
                              ^^^^^^^^^^^^^^^^^^^
  File "/usr/lib/python3.12/http/client.py", line 292, in _read_status
    line = str(self.fp.readline(_MAXLINE + 1), "iso-8859-1")
               ^^^^^^^^^^^^^^^^^^^^^^^^^^^^^^
  File "/usr/lib/python3.12/socket.py", line 707, in readinto
    return self._sock.recv_into(b)
           ^^^^^^^^^^^^^^^^^^^^^^^
  File "/usr/lib/python3.12/ssl.py", line 1252, in recv_into
    return self.read(nbytes, buffer)
           ^^^^^^^^^^^^^^^^^^^^^^^^^
  File "/usr/lib/python3.12/ssl.py", line 1104, in read
    return self._sslobj.read(len, buffer)
           ^^^^^^^^^^^^^^^^^^^^^^^^^^^^^^
TimeoutError: The read operation timed out

The above exception was the direct cause of the following exception:

Traceback (most recent call last):
  File "/home/user/venv/lib/python3.12/site-packages/requests/adapters.py", line 667, in send
    resp = conn.urlopen(
           ^^^^^^^^^^^^^
  File "/home/user/venv/lib/python3.12/site-packages/urllib3/connectionpool.py", line 841, in urlopen
    retries = retries.increment(
              ^^^^^^^^^^^^^^^^^^
  File "/home/user/venv/lib/python3.12/site-packages/urllib3/util/retry.py", line 474, in increment
    raise reraise(type(error), error, _stacktrace)
          ^^^^^^^^^^^^^^^^^^^^^^^^^^^^^^^^^^^^^^^^
  File "/home/user/venv/lib/python3.12/site-packages/urllib3/util/util.py", line 39, in reraise
    raise value
  File "/home/user/venv/lib/python3.12/site-packages/urllib3/connectionpool.py", line 787, in urlopen
    response = self._make_request(
               ^^^^^^^^^^^^^^^^^^^
  File "/home/user/venv/lib/python3.12/site-packages/urllib3/connectionpool.py", line 536, in _make_request
    self._raise_timeout(err=e, url=url, timeout_value=read_timeout)
  File "/home/user/venv/lib/python3.12/site-packages/urllib3/connectionpool.py", line 367, in _raise_timeout
    raise ReadTimeoutError(
urllib3.exceptions.ReadTimeoutError: HTTPSConnectionPool(host='api.telegram.org', port=443): Read timed out. (read timeout=25)

During handling of the above exception, another exception occurred:

Traceback (most recent call last):
  File "/home/user/venv/lib/python3.12/site-packages/telebot/__init__.py", line 1110, in infinity_polling
    self.polling(non_stop=True, timeout=timeout, long_polling_timeout=long_polling_timeout,
  File "/home/user/venv/lib/python3.12/site-packages/telebot/__init__.py", line 1198, in polling
    self.__threaded_polling(non_stop=non_stop, interval=interval, timeout=timeout, long_polling_timeout=long_polling_timeout,
  File "/home/user/venv/lib/python3.12/site-packages/telebot/__init__.py", line 1273, in __threaded_polling
    raise e
  File "/home/user/venv/lib/python3.12/site-packages/telebot/__init__.py", line 1234, in __threaded_polling
    polling_thread.raise_exceptions()
  File "/home/user/venv/lib/python3.12/site-packages/telebot/util.py", line 111, in raise_exceptions
    raise self.exception_info
  File "/home/user/venv/lib/python3.12/site-packages/telebot/util.py", line 93, in run
    task(*args, **kwargs)
  File "/home/user/venv/lib/python3.12/site-packages/telebot/__init__.py", line 688, in __retrieve_updates
    updates = self.get_updates(offset=(self.last_update_id + 1),
             ^^^^^^^^^^^^^^^^^^^^^^^^^^^^^^^^^^^^^^^^^^^^^^^^^^
  File "/home/user/venv/lib/python3.12/site-packages/telebot/__init__.py", line 660, in get_updates
    json_updates = apihelper.get_updates(
                   ^^^^^^^^^^^^^^^^^^^^^^
  File "/home/user/venv/lib/python3.12/site-packages/telebot/apihelper.py", line 332, in get_updates
    return _make_request(token, method_url, params=payload)
           ^^^^^^^^^^^^^^^^^^^^^^^^^^^^^^^^^^^^^^^^^^^^^^^^
  File "/home/user/venv/lib/python3.12/site-packages/telebot/apihelper.py", line 162, in _make_request
    result = _get_req_session().request(
             ^^^^^^^^^^^^^^^^^^^^^^^^^^^
  File "/home/user/venv/lib/python3.12/site-packages/requests/sessions.py", line 589, in request
    resp = self.send(prep, **send_kwargs)
           ^^^^^^^^^^^^^^^^^^^^^^^^^^^^^^
  File "/home/user/venv/lib/python3.12/site-packages/requests/sessions.py", line 703, in send
    r = adapter.send(request, **kwargs)
        ^^^^^^^^^^^^^^^^^^^^^^^^^^^^^^^
  File "/home/user/venv/lib/python3.12/site-packages/requests/adapters.py", line 713, in send
    raise ReadTimeout(e, request=request)
requests.exceptions.ReadTimeout: HTTPSConnectionPool(host='api.telegram.org', port=443): Read timed out. (read timeout=25)
"
2024-12-31 19:19:42,333 (__init__.py:1115 MainThread) ERROR - TeleBot: "Infinity polling exception: HTTPSConnectionPool(host='api.telegram.org', port=443): Read timed out. (read timeout=25)"
2024-12-31 19:19:42,336 (__init__.py:1117 MainThread) ERROR - TeleBot: "Exception traceback:
Traceback (most recent call last):
  File "/home/user/venv/lib/python3.12/site-packages/urllib3/connectionpool.py", line 534, in _make_request
    response = conn.getresponse()
               ^^^^^^^^^^^^^^^^^^
  File "/home/user/venv/lib/python3.12/site-packages/urllib3/connection.py", line 516, in getresponse
    httplib_response = super().getresponse()
                       ^^^^^^^^^^^^^^^^^^^^^
  File "/usr/lib/python3.12/http/client.py", line 1428, in getresponse
    response.begin()
  File "/usr/lib/python3.12/http/client.py", line 331, in begin
    version, status, reason = self._read_status()
                              ^^^^^^^^^^^^^^^^^^^
  File "/usr/lib/python3.12/http/client.py", line 292, in _read_status
    line = str(self.fp.readline(_MAXLINE + 1), "iso-8859-1")
               ^^^^^^^^^^^^^^^^^^^^^^^^^^^^^^
  File "/usr/lib/python3.12/socket.py", line 707, in readinto
    return self._sock.recv_into(b)
           ^^^^^^^^^^^^^^^^^^^^^^^
  File "/usr/lib/python3.12/ssl.py", line 1252, in recv_into
    return self.read(nbytes, buffer)
           ^^^^^^^^^^^^^^^^^^^^^^^^^
  File "/usr/lib/python3.12/ssl.py", line 1104, in read
    return self._sslobj.read(len, buffer)
           ^^^^^^^^^^^^^^^^^^^^^^^^^^^^^^
TimeoutError: The read operation timed out

The above exception was the direct cause of the following exception:

Traceback (most recent call last):
  File "/home/user/venv/lib/python3.12/site-packages/requests/adapters.py", line 667, in send
    resp = conn.urlopen(
           ^^^^^^^^^^^^^
  File "/home/user/venv/lib/python3.12/site-packages/urllib3/connectionpool.py", line 841, in urlopen
    retries = retries.increment(
              ^^^^^^^^^^^^^^^^^^
  File "/home/user/venv/lib/python3.12/site-packages/urllib3/util/retry.py", line 474, in increment
    raise reraise(type(error), error, _stacktrace)
          ^^^^^^^^^^^^^^^^^^^^^^^^^^^^^^^^^^^^^^^^
  File "/home/user/venv/lib/python3.12/site-packages/urllib3/util/util.py", line 39, in reraise
    raise value
  File "/home/user/venv/lib/python3.12/site-packages/urllib3/connectionpool.py", line 787, in urlopen
    response = self._make_request(
               ^^^^^^^^^^^^^^^^^^^
  File "/home/user/venv/lib/python3.12/site-packages/urllib3/connectionpool.py", line 536, in _make_request
    self._raise_timeout(err=e, url=url, timeout_value=read_timeout)
  File "/home/user/venv/lib/python3.12/site-packages/urllib3/connectionpool.py", line 367, in _raise_timeout
    raise ReadTimeoutError(
urllib3.exceptions.ReadTimeoutError: HTTPSConnectionPool(host='api.telegram.org', port=443): Read timed out. (read timeout=25)

During handling of the above exception, another exception occurred:

Traceback (most recent call last):
  File "/home/user/venv/lib/python3.12/site-packages/telebot/__init__.py", line 1110, in infinity_polling
    self.polling(non_stop=True, timeout=timeout, long_polling_timeout=long_polling_timeout,
  File "/home/user/venv/lib/python3.12/site-packages/telebot/__init__.py", line 1198, in polling
    self.__threaded_polling(non_stop=non_stop, interval=interval, timeout=timeout, long_polling_timeout=long_polling_timeout,
  File "/home/user/venv/lib/python3.12/site-packages/telebot/__init__.py", line 1273, in __threaded_polling
    raise e
  File "/home/user/venv/lib/python3.12/site-packages/telebot/__init__.py", line 1234, in __threaded_polling
    polling_thread.raise_exceptions()
  File "/home/user/venv/lib/python3.12/site-packages/telebot/util.py", line 111, in raise_exceptions
    raise self.exception_info
  File "/home/user/venv/lib/python3.12/site-packages/telebot/util.py", line 93, in run
    task(*args, **kwargs)
  File "/home/user/venv/lib/python3.12/site-packages/telebot/__init__.py", line 688, in __retrieve_updates
    updates = self.get_updates(offset=(self.last_update_id + 1),
             ^^^^^^^^^^^^^^^^^^^^^^^^^^^^^^^^^^^^^^^^^^^^^^^^^^
  File "/home/user/venv/lib/python3.12/site-packages/telebot/__init__.py", line 660, in get_updates
    json_updates = apihelper.get_updates(
                   ^^^^^^^^^^^^^^^^^^^^^^
  File "/home/user/venv/lib/python3.12/site-packages/telebot/apihelper.py", line 332, in get_updates
    return _make_request(token, method_url, params=payload)
           ^^^^^^^^^^^^^^^^^^^^^^^^^^^^^^^^^^^^^^^^^^^^^^^^
  File "/home/user/venv/lib/python3.12/site-packages/telebot/apihelper.py", line 162, in _make_request
    result = _get_req_session().request(
             ^^^^^^^^^^^^^^^^^^^^^^^^^^^
  File "/home/user/venv/lib/python3.12/site-packages/requests/sessions.py", line 589, in request
    resp = self.send(prep, **send_kwargs)
           ^^^^^^^^^^^^^^^^^^^^^^^^^^^^^^
  File "/home/user/venv/lib/python3.12/site-packages/requests/sessions.py", line 703, in send
    r = adapter.send(request, **kwargs)
        ^^^^^^^^^^^^^^^^^^^^^^^^^^^^^^^
  File "/home/user/venv/lib/python3.12/site-packages/requests/adapters.py", line 713, in send
    raise ReadTimeout(e, request=request)
requests.exceptions.ReadTimeout: HTTPSConnectionPool(host='api.telegram.org', port=443): Read timed out. (read timeout=25)
"
2024-12-31 20:08:48,927 (__init__.py:1115 MainThread) ERROR - TeleBot: "Infinity polling exception: HTTPSConnectionPool(host='api.telegram.org', port=443): Read timed out. (read timeout=25)"
2024-12-31 20:08:48,930 (__init__.py:1117 MainThread) ERROR - TeleBot: "Exception traceback:
Traceback (most recent call last):
  File "/home/user/venv/lib/python3.12/site-packages/urllib3/connectionpool.py", line 534, in _make_request
    response = conn.getresponse()
               ^^^^^^^^^^^^^^^^^^
  File "/home/user/venv/lib/python3.12/site-packages/urllib3/connection.py", line 516, in getresponse
    httplib_response = super().getresponse()
                       ^^^^^^^^^^^^^^^^^^^^^
  File "/usr/lib/python3.12/http/client.py", line 1428, in getresponse
    response.begin()
  File "/usr/lib/python3.12/http/client.py", line 331, in begin
    version, status, reason = self._read_status()
                              ^^^^^^^^^^^^^^^^^^^
  File "/usr/lib/python3.12/http/client.py", line 292, in _read_status
    line = str(self.fp.readline(_MAXLINE + 1), "iso-8859-1")
               ^^^^^^^^^^^^^^^^^^^^^^^^^^^^^^
  File "/usr/lib/python3.12/socket.py", line 707, in readinto
    return self._sock.recv_into(b)
           ^^^^^^^^^^^^^^^^^^^^^^^
  File "/usr/lib/python3.12/ssl.py", line 1252, in recv_into
    return self.read(nbytes, buffer)
           ^^^^^^^^^^^^^^^^^^^^^^^^^
  File "/usr/lib/python3.12/ssl.py", line 1104, in read
    return self._sslobj.read(len, buffer)
           ^^^^^^^^^^^^^^^^^^^^^^^^^^^^^^
TimeoutError: The read operation timed out

The above exception was the direct cause of the following exception:

Traceback (most recent call last):
  File "/home/user/venv/lib/python3.12/site-packages/requests/adapters.py", line 667, in send
    resp = conn.urlopen(
           ^^^^^^^^^^^^^
  File "/home/user/venv/lib/python3.12/site-packages/urllib3/connectionpool.py", line 841, in urlopen
    retries = retries.increment(
              ^^^^^^^^^^^^^^^^^^
  File "/home/user/venv/lib/python3.12/site-packages/urllib3/util/retry.py", line 474, in increment
    raise reraise(type(error), error, _stacktrace)
          ^^^^^^^^^^^^^^^^^^^^^^^^^^^^^^^^^^^^^^^^
  File "/home/user/venv/lib/python3.12/site-packages/urllib3/util/util.py", line 39, in reraise
    raise value
  File "/home/user/venv/lib/python3.12/site-packages/urllib3/connectionpool.py", line 787, in urlopen
    response = self._make_request(
               ^^^^^^^^^^^^^^^^^^^
  File "/home/user/venv/lib/python3.12/site-packages/urllib3/connectionpool.py", line 536, in _make_request
    self._raise_timeout(err=e, url=url, timeout_value=read_timeout)
  File "/home/user/venv/lib/python3.12/site-packages/urllib3/connectionpool.py", line 367, in _raise_timeout
    raise ReadTimeoutError(
urllib3.exceptions.ReadTimeoutError: HTTPSConnectionPool(host='api.telegram.org', port=443): Read timed out. (read timeout=25)

During handling of the above exception, another exception occurred:

Traceback (most recent call last):
  File "/home/user/venv/lib/python3.12/site-packages/telebot/__init__.py", line 1110, in infinity_polling
    self.polling(non_stop=True, timeout=timeout, long_polling_timeout=long_polling_timeout,
  File "/home/user/venv/lib/python3.12/site-packages/telebot/__init__.py", line 1198, in polling
    self.__threaded_polling(non_stop=non_stop, interval=interval, timeout=timeout, long_polling_timeout=long_polling_timeout,
  File "/home/user/venv/lib/python3.12/site-packages/telebot/__init__.py", line 1273, in __threaded_polling
    raise e
  File "/home/user/venv/lib/python3.12/site-packages/telebot/__init__.py", line 1234, in __threaded_polling
    polling_thread.raise_exceptions()
  File "/home/user/venv/lib/python3.12/site-packages/telebot/util.py", line 111, in raise_exceptions
    raise self.exception_info
  File "/home/user/venv/lib/python3.12/site-packages/telebot/util.py", line 93, in run
    task(*args, **kwargs)
  File "/home/user/venv/lib/python3.12/site-packages/telebot/__init__.py", line 688, in __retrieve_updates
    updates = self.get_updates(offset=(self.last_update_id + 1),
             ^^^^^^^^^^^^^^^^^^^^^^^^^^^^^^^^^^^^^^^^^^^^^^^^^^
  File "/home/user/venv/lib/python3.12/site-packages/telebot/__init__.py", line 660, in get_updates
    json_updates = apihelper.get_updates(
                   ^^^^^^^^^^^^^^^^^^^^^^
  File "/home/user/venv/lib/python3.12/site-packages/telebot/apihelper.py", line 332, in get_updates
    return _make_request(token, method_url, params=payload)
           ^^^^^^^^^^^^^^^^^^^^^^^^^^^^^^^^^^^^^^^^^^^^^^^^
  File "/home/user/venv/lib/python3.12/site-packages/telebot/apihelper.py", line 162, in _make_request
    result = _get_req_session().request(
             ^^^^^^^^^^^^^^^^^^^^^^^^^^^
  File "/home/user/venv/lib/python3.12/site-packages/requests/sessions.py", line 589, in request
    resp = self.send(prep, **send_kwargs)
           ^^^^^^^^^^^^^^^^^^^^^^^^^^^^^^
  File "/home/user/venv/lib/python3.12/site-packages/requests/sessions.py", line 703, in send
    r = adapter.send(request, **kwargs)
        ^^^^^^^^^^^^^^^^^^^^^^^^^^^^^^^
  File "/home/user/venv/lib/python3.12/site-packages/requests/adapters.py", line 713, in send
    raise ReadTimeout(e, request=request)
requests.exceptions.ReadTimeout: HTTPSConnectionPool(host='api.telegram.org', port=443): Read timed out. (read timeout=25)
"
[01/Jan/2025 00:37:33] "CONNECT example.com:443 HTTP/1.1" 404 179
[01/Jan/2025 03:23:41] "GET /.env HTTP/1.1" 200 212
--- Logging error ---
03:23:44 [Q] ERROR You can't write against a read only replica.
Traceback (most recent call last):
  File "/home/user/venv/lib/python3.12/site-packages/django_q/cluster.py", line 345, in pusher
    task_set = broker.dequeue()
               ^^^^^^^^^^^^^^^^
  File "/home/user/venv/lib/python3.12/site-packages/django_q/brokers/redis_broker.py", line 21, in dequeue
    task = self.connection.blpop(self.list_key, 1)
           ^^^^^^^^^^^^^^^^^^^^^^^^^^^^^^^^^^^^^^^
  File "/home/user/venv/lib/python3.12/site-packages/redis/client.py", line 1900, in blpop
    return self.execute_command('BLPOP', *keys)
           ^^^^^^^^^^^^^^^^^^^^^^^^^^^^^^^^^^^^
  File "/home/user/venv/lib/python3.12/site-packages/redis/client.py", line 901, in execute_command
    return self.parse_response(conn, command_name, **options)
           ^^^^^^^^^^^^^^^^^^^^^^^^^^^^^^^^^^^^^^^^^^^^^^^^^^
  File "/home/user/venv/lib/python3.12/site-packages/redis/client.py", line 915, in parse_response
    response = connection.read_response()
               ^^^^^^^^^^^^^^^^^^^^^^^^^^
  File "/home/user/venv/lib/python3.12/site-packages/redis/connection.py", line 756, in read_response
    raise response
redis.exceptions.ResponseError: UNBLOCKED force unblock from blocking operation, instance state changed (master -> replica?)

During handling of the above exception, another exception occurred:

Traceback (most recent call last):
  File "/usr/lib/python3.12/logging/__init__.py", line 1160, in emit
    msg = self.format(record)
          ^^^^^^^^^^^^^^^^^^^
  File "/usr/lib/python3.12/logging/__init__.py", line 999, in format
    return fmt.format(record)
           ^^^^^^^^^^^^^^^^^^
  File "/usr/lib/python3.12/logging/__init__.py", line 703, in format
    record.message = record.getMessage()
                     ^^^^^^^^^^^^^^^^^^^
  File "/usr/lib/python3.12/logging/__init__.py", line 392, in getMessage
    msg = msg % self.args
          ~~~~^~~~~~~~~~~
TypeError: not all arguments converted during string formatting
Call stack:
  File "/home/user/KepfutsiyBot/manage.py", line 22, in <module>
    main()
  File "/home/user/KepfutsiyBot/manage.py", line 18, in main
    execute_from_command_line(sys.argv)
  File "/home/user/venv/lib/python3.12/site-packages/django/core/management/__init__.py", line 419, in execute_from_command_line
    utility.execute()
  File "/home/user/venv/lib/python3.12/site-packages/django/core/management/__init__.py", line 413, in execute
    self.fetch_command(subcommand).run_from_argv(self.argv)
  File "/home/user/venv/lib/python3.12/site-packages/django/core/management/base.py", line 354, in run_from_argv
    self.execute(*args, **cmd_options)
  File "/home/user/venv/lib/python3.12/site-packages/django/core/management/base.py", line 398, in execute
    output = self.handle(*args, **options)
  File "/home/user/venv/lib/python3.12/site-packages/django_q/management/commands/qcluster.py", line 22, in handle
    q.start()
  File "/home/user/venv/lib/python3.12/site-packages/django_q/cluster.py", line 78, in start
    self.sentinel.start()
  File "/usr/lib/python3.12/multiprocessing/process.py", line 121, in start
    self._popen = self._Popen(self)
  File "/usr/lib/python3.12/multiprocessing/context.py", line 224, in _Popen
    return _default_context.get_context().Process._Popen(process_obj)
  File "/usr/lib/python3.12/multiprocessing/context.py", line 282, in _Popen
    return Popen(process_obj)
  File "/usr/lib/python3.12/multiprocessing/popen_fork.py", line 19, in __init__
    self._launch(process_obj)
  File "/usr/lib/python3.12/multiprocessing/popen_fork.py", line 71, in _launch
    code = process_obj._bootstrap(parent_sentinel=child_r)
  File "/usr/lib/python3.12/multiprocessing/process.py", line 314, in _bootstrap
    self.run()
  File "/usr/lib/python3.12/multiprocessing/process.py", line 108, in run
    self._target(*self._args, **self._kwargs)
  File "/home/user/venv/lib/python3.12/site-packages/django_q/cluster.py", line 168, in __init__
    self.start()
  File "/home/user/venv/lib/python3.12/site-packages/django_q/cluster.py", line 172, in start
    self.spawn_cluster()
  File "/home/user/venv/lib/python3.12/site-packages/django_q/cluster.py", line 248, in spawn_cluster
    self.pusher = self.spawn_pusher()
  File "/home/user/venv/lib/python3.12/site-packages/django_q/cluster.py", line 201, in spawn_pusher
    return self.spawn_process(pusher, self.task_queue, self.event_out, self.broker)
  File "/home/user/venv/lib/python3.12/site-packages/django_q/cluster.py", line 197, in spawn_process
    p.start()
  File "/usr/lib/python3.12/multiprocessing/process.py", line 121, in start
    self._popen = self._Popen(self)
  File "/usr/lib/python3.12/multiprocessing/context.py", line 224, in _Popen
    return _default_context.get_context().Process._Popen(process_obj)
  File "/usr/lib/python3.12/multiprocessing/context.py", line 282, in _Popen
    return Popen(process_obj)
  File "/usr/lib/python3.12/multiprocessing/popen_fork.py", line 19, in __init__
    self._launch(process_obj)
  File "/usr/lib/python3.12/multiprocessing/popen_fork.py", line 71, in _launch
    code = process_obj._bootstrap(parent_sentinel=child_r)
  File "/usr/lib/python3.12/multiprocessing/process.py", line 314, in _bootstrap
    self.run()
  File "/usr/lib/python3.12/multiprocessing/process.py", line 108, in run
    self._target(*self._args, **self._kwargs)
  File "/home/user/venv/lib/python3.12/site-packages/django_q/cluster.py", line 347, in pusher
    logger.error(e, traceback.format_exc())
Message: ResponseError('UNBLOCKED force unblock from blocking operation, instance state changed (master -> replica?)')
Arguments: ('Traceback (most recent call last):\n  File "/home/user/venv/lib/python3.12/site-packages/django_q/cluster.py", line 345, in pusher\n    task_set = broker.dequeue()\n               ^^^^^^^^^^^^^^^^\n  File "/home/user/venv/lib/python3.12/site-packages/django_q/brokers/redis_broker.py", line 21, in dequeue\n    task = self.connection.blpop(self.list_key, 1)\n           ^^^^^^^^^^^^^^^^^^^^^^^^^^^^^^^^^^^^^^^\n  File "/home/user/venv/lib/python3.12/site-packages/redis/client.py", line 1900, in blpop\n    return self.execute_command(\'BLPOP\', *keys)\n           ^^^^^^^^^^^^^^^^^^^^^^^^^^^^^^^^^^^^\n  File "/home/user/venv/lib/python3.12/site-packages/redis/client.py", line 901, in execute_command\n    return self.parse_response(conn, command_name, **options)\n           ^^^^^^^^^^^^^^^^^^^^^^^^^^^^^^^^^^^^^^^^^^^^^^^^^^\n  File "/home/user/venv/lib/python3.12/site-packages/redis/client.py", line 915, in parse_response\n    response = connection.read_response()\n               ^^^^^^^^^^^^^^^^^^^^^^^^^^\n  File "/home/user/venv/lib/python3.12/site-packages/redis/connection.py", line 756, in read_response\n    raise response\nredis.exceptions.ResponseError: UNBLOCKED force unblock from blocking operation, instance state changed (master -> replica?)\n',)
03:23:44 [Q] ERROR You can't write against a read only replica.
03:23:45 [Q] ERROR You can't write against a read only replica.
03:23:45 [Q] ERROR You can't write against a read only replica.
03:23:46 [Q] ERROR You can't write against a read only replica.
03:23:46 [Q] ERROR You can't write against a read only replica.
03:23:47 [Q] ERROR You can't write against a read only replica.
03:23:47 [Q] ERROR You can't write against a read only replica.
03:23:48 [Q] ERROR You can't write against a read only replica.
03:23:48 [Q] ERROR You can't write against a read only replica.
03:23:49 [Q] ERROR You can't write against a read only replica.
03:23:49 [Q] ERROR You can't write against a read only replica.
03:23:54 [Q] INFO Process-1:3 stopped pushing tasks
03:23:54 [Q] ERROR reincarnated pusher Process-1:3 after sudden death
03:23:54 [Q] INFO Process-1:4 pushing tasks at 17514
[01/Jan/2025 03:45:38] "GET / HTTP/1.1" 404 179
[01/Jan/2025 05:43:51] "GET /admin/bot_notifier/botuser/ HTTP/1.1" 200 8129
[01/Jan/2025 05:43:51] "GET /favicon.ico HTTP/1.1" 404 179
[01/Jan/2025 06:06:25] "GET /admin/bot_notifier/botuser/ HTTP/1.1" 200 8129
[01/Jan/2025 06:06:25] "GET /favicon.ico HTTP/1.1" 404 179
[01/Jan/2025 08:44:09] "GET / HTTP/1.1" 404 179
[01/Jan/2025 08:51:07] "GET /favicon.ico HTTP/1.1" 404 179
[01/Jan/2025 09:42:12] "GET /admin/bot_notifier/botuser/ HTTP/1.1" 200 8129
[01/Jan/2025 09:42:12] "GET /favicon.ico HTTP/1.1" 404 179
[01/Jan/2025 09:42:15] "GET /admin/bot_notifier/sentence/ HTTP/1.1" 200 7782
[01/Jan/2025 09:42:16] "GET /admin/jsi18n/ HTTP/1.1" 200 3325
[01/Jan/2025 10:01:38] "GET / HTTP/1.0" 404 179
[01/Jan/2025 11:19:21] code 400, message Bad request version ("\x02\x15rtTc\x03ø\x00V\x13\x02\x13\x03\x13\x01À,À0À+À/Ì©Ì¨\x00\x9f\x00\x9eÌªÀ¯À\xadÀ®À¬À$À(À#À'À")
[01/Jan/2025 11:19:21] You're accessing the development server over HTTPS, but it only supports HTTP.

[01/Jan/2025 11:25:23] "GET //libs/js/iframe.js HTTP/1.1" 404 179
[01/Jan/2025 11:29:21] code 400, message Bad request version ('/]qß×')
[01/Jan/2025 11:29:21] You're accessing the development server over HTTPS, but it only supports HTTP.

[01/Jan/2025 11:29:34] "GET / HTTP/1.1" 404 179
[01/Jan/2025 11:30:09] "GET /favicon.ico HTTP/1.1" 404 179
[01/Jan/2025 11:35:22] "GET //admin/config.php HTTP/1.1" 302 0
[01/Jan/2025 11:35:23] "GET /admin/login/?next=/admin/config.php HTTP/1.1" 200 2299
12:25:05 [Q] INFO Enqueued 1
12:25:05 [Q] INFO Process-1 created a task from schedule [sent nimadur]
12:25:05 [Q] INFO Process-1:1 processing [oklahoma-california-uncle-avocado]
12:25:08 [Q] INFO Processed [oklahoma-california-uncle-avocado]
[01/Jan/2025 13:55:08] "GET /.env HTTP/1.1" 200 212
--- Logging error ---
Traceback (most recent call last):
  File "/home/user/venv/lib/python3.12/site-packages/django_q/cluster.py", line 345, in pusher
    task_set = broker.dequeue()
               ^^^^^^^^^^^^^^^^
  File "/home/user/venv/lib/python3.12/site-packages/django_q/brokers/redis_broker.py", line 21, in dequeue
    task = self.connection.blpop(self.list_key, 1)
           ^^^^^^^^^^^^^^^^^^^^^^^^^^^^^^^^^^^^^^^
  File "/home/user/venv/lib/python3.12/site-packages/redis/client.py", line 1900, in blpop
    return self.execute_command('BLPOP', *keys)
           ^^^^^^^^^^^^^^^^^^^^^^^^^^^^^^^^^^^^
  File "/home/user/venv/lib/python3.12/site-packages/redis/client.py", line 901, in execute_command
    return self.parse_response(conn, command_name, **options)
           ^^^^^^^^^^^^^^^^^^^^^^^^^^^^^^^^^^^^^^^^^^^^^^^^^^
  File "/home/user/venv/lib/python3.12/site-packages/redis/client.py", line 915, in parse_response
    response = connection.read_response()
               ^^^^^^^^^^^^^^^^^^^^^^^^^^
  File "/home/user/venv/lib/python3.12/site-packages/redis/connection.py", line 756, in read_response
    raise response
redis.exceptions.ResponseError: UNBLOCKED force unblock from blocking operation, instance state changed (master -> replica?)

During handling of the above exception, another exception occurred:

Traceback (most recent call last):
  File "/usr/lib/python3.12/logging/__init__.py", line 1160, in emit
    msg = self.format(record)
          ^^^^^^^^^^^^^^^^^^^
  File "/usr/lib/python3.12/logging/__init__.py", line 999, in format
    return fmt.format(record)
           ^^^^^^^^^^^^^^^^^^
  File "/usr/lib/python3.12/logging/__init__.py", line 703, in format
    record.message = record.getMessage()
                     ^^^^^^^^^^^^^^^^^^^
  File "/usr/lib/python3.12/logging/__init__.py", line 392, in getMessage
    msg = msg % self.args
          ~~~~^~~~~~~~~~~
TypeError: not all arguments converted during string formatting
Call stack:
  File "/home/user/KepfutsiyBot/manage.py", line 22, in <module>
    main()
  File "/home/user/KepfutsiyBot/manage.py", line 18, in main
    execute_from_command_line(sys.argv)
  File "/home/user/venv/lib/python3.12/site-packages/django/core/management/__init__.py", line 419, in execute_from_command_line
    utility.execute()
  File "/home/user/venv/lib/python3.12/site-packages/django/core/management/__init__.py", line 413, in execute
    self.fetch_command(subcommand).run_from_argv(self.argv)
  File "/home/user/venv/lib/python3.12/site-packages/django/core/management/base.py", line 354, in run_from_argv
    self.execute(*args, **cmd_options)
  File "/home/user/venv/lib/python3.12/site-packages/django/core/management/base.py", line 398, in execute
    output = self.handle(*args, **options)
  File "/home/user/venv/lib/python3.12/site-packages/django_q/management/commands/qcluster.py", line 22, in handle
    q.start()
  File "/home/user/venv/lib/python3.12/site-packages/django_q/cluster.py", line 78, in start
    self.sentinel.start()
  File "/usr/lib/python3.12/multiprocessing/process.py", line 121, in start
    self._popen = self._Popen(self)
  File "/usr/lib/python3.12/multiprocessing/context.py", line 224, in _Popen
    return _default_context.get_context().Process._Popen(process_obj)
  File "/usr/lib/python3.12/multiprocessing/context.py", line 282, in _Popen
    return Popen(process_obj)
  File "/usr/lib/python3.12/multiprocessing/popen_fork.py", line 19, in __init__
    self._launch(process_obj)
  File "/usr/lib/python3.12/multiprocessing/popen_fork.py", line 71, in _launch
    code = process_obj._bootstrap(parent_sentinel=child_r)
  File "/usr/lib/python3.12/multiprocessing/process.py", line 314, in _bootstrap
    self.run()
  File "/usr/lib/python3.12/multiprocessing/process.py", line 108, in run
    self._target(*self._args, **self._kwargs)
  File "/home/user/venv/lib/python3.12/site-packages/django_q/cluster.py", line 168, in __init__
    self.start()
  File "/home/user/venv/lib/python3.12/site-packages/django_q/cluster.py", line 173, in start
    self.guard()
  File "/home/user/venv/lib/python3.12/site-packages/django_q/cluster.py", line 281, in guard
    self.reincarnate(self.pusher)
  File "/home/user/venv/lib/python3.12/site-packages/django_q/cluster.py", line 222, in reincarnate
    self.pusher = self.spawn_pusher()
  File "/home/user/venv/lib/python3.12/site-packages/django_q/cluster.py", line 201, in spawn_pusher
    return self.spawn_process(pusher, self.task_queue, self.event_out, self.broker)
  File "/home/user/venv/lib/python3.12/site-packages/django_q/cluster.py", line 197, in spawn_process
    p.start()
  File "/usr/lib/python3.12/multiprocessing/process.py", line 121, in start
    self._popen = self._Popen(self)
  File "/usr/lib/python3.12/multiprocessing/context.py", line 224, in _Popen
    return _default_context.get_context().Process._Popen(process_obj)
  File "/usr/lib/python3.12/multiprocessing/context.py", line 282, in _Popen
    return Popen(process_obj)
  File "/usr/lib/python3.12/multiprocessing/popen_fork.py", line 19, in __init__
    self._launch(process_obj)
  File "/usr/lib/python3.12/multiprocessing/popen_fork.py", line 71, in _launch
    code = process_obj._bootstrap(parent_sentinel=child_r)
  File "/usr/lib/python3.12/multiprocessing/process.py", line 314, in _bootstrap
    self.run()
  File "/usr/lib/python3.12/multiprocessing/process.py", line 108, in run
    self._target(*self._args, **self._kwargs)
  File "/home/user/venv/lib/python3.12/site-packages/django_q/cluster.py", line 347, in pusher
    logger.error(e, traceback.format_exc())
Message: ResponseError('UNBLOCKED force unblock from blocking operation, instance state changed (master -> replica?)')
Arguments: ('Traceback (most recent call last):\n  File "/home/user/venv/lib/python3.12/site-packages/django_q/cluster.py", line 345, in pusher\n    task_set = broker.dequeue()\n               ^^^^^^^^^^^^^^^^\n  File "/home/user/venv/lib/python3.12/site-packages/django_q/brokers/redis_broker.py", line 21, in dequeue\n    task = self.connection.blpop(self.list_key, 1)\n           ^^^^^^^^^^^^^^^^^^^^^^^^^^^^^^^^^^^^^^^\n  File "/home/user/venv/lib/python3.12/site-packages/redis/client.py", line 1900, in blpop\n    return self.execute_command(\'BLPOP\', *keys)\n           ^^^^^^^^^^^^^^^^^^^^^^^^^^^^^^^^^^^^\n  File "/home/user/venv/lib/python3.12/site-packages/redis/client.py", line 901, in execute_command\n    return self.parse_response(conn, command_name, **options)\n           ^^^^^^^^^^^^^^^^^^^^^^^^^^^^^^^^^^^^^^^^^^^^^^^^^^\n  File "/home/user/venv/lib/python3.12/site-packages/redis/client.py", line 915, in parse_response\n    response = connection.read_response()\n               ^^^^^^^^^^^^^^^^^^^^^^^^^^\n  File "/home/user/venv/lib/python3.12/site-packages/redis/connection.py", line 756, in read_response\n    raise response\nredis.exceptions.ResponseError: UNBLOCKED force unblock from blocking operation, instance state changed (master -> replica?)\n',)
13:55:23 [Q] INFO Process-1:4 stopped pushing tasks
13:55:23 [Q] ERROR reincarnated pusher Process-1:4 after sudden death
13:55:23 [Q] INFO Process-1:5 pushing tasks at 24916
[01/Jan/2025 18:04:49] code 400, message Bad request version ('À\x14À')
[01/Jan/2025 18:04:49] You're accessing the development server over HTTPS, but it only supports HTTP.

[01/Jan/2025 18:42:40] "GET /.env HTTP/1.1" 200 212
--- Logging error ---
Traceback (most recent call last):
  File "/home/user/venv/lib/python3.12/site-packages/django_q/cluster.py", line 345, in pusher
    task_set = broker.dequeue()
               ^^^^^^^^^^^^^^^^
  File "/home/user/venv/lib/python3.12/site-packages/django_q/brokers/redis_broker.py", line 21, in dequeue
    task = self.connection.blpop(self.list_key, 1)
           ^^^^^^^^^^^^^^^^^^^^^^^^^^^^^^^^^^^^^^^
  File "/home/user/venv/lib/python3.12/site-packages/redis/client.py", line 1900, in blpop
    return self.execute_command('BLPOP', *keys)
           ^^^^^^^^^^^^^^^^^^^^^^^^^^^^^^^^^^^^
  File "/home/user/venv/lib/python3.12/site-packages/redis/client.py", line 901, in execute_command
    return self.parse_response(conn, command_name, **options)
           ^^^^^^^^^^^^^^^^^^^^^^^^^^^^^^^^^^^^^^^^^^^^^^^^^^
  File "/home/user/venv/lib/python3.12/site-packages/redis/client.py", line 915, in parse_response
    response = connection.read_response()
               ^^^^^^^^^^^^^^^^^^^^^^^^^^
  File "/home/user/venv/lib/python3.12/site-packages/redis/connection.py", line 756, in read_response
    raise response
redis.exceptions.ResponseError: UNBLOCKED force unblock from blocking operation, instance state changed (master -> replica?)

During handling of the above exception, another exception occurred:

Traceback (most recent call last):
  File "/usr/lib/python3.12/logging/__init__.py", line 1160, in emit
    msg = self.format(record)
          ^^^^^^^^^^^^^^^^^^^
  File "/usr/lib/python3.12/logging/__init__.py", line 999, in format
    return fmt.format(record)
           ^^^^^^^^^^^^^^^^^^
  File "/usr/lib/python3.12/logging/__init__.py", line 703, in format
    record.message = record.getMessage()
                     ^^^^^^^^^^^^^^^^^^^
  File "/usr/lib/python3.12/logging/__init__.py", line 392, in getMessage
    msg = msg % self.args
          ~~~~^~~~~~~~~~~
TypeError: not all arguments converted during string formatting
Call stack:
  File "/home/user/KepfutsiyBot/manage.py", line 22, in <module>
    main()
  File "/home/user/KepfutsiyBot/manage.py", line 18, in main
    execute_from_command_line(sys.argv)
  File "/home/user/venv/lib/python3.12/site-packages/django/core/management/__init__.py", line 419, in execute_from_command_line
    utility.execute()
  File "/home/user/venv/lib/python3.12/site-packages/django/core/management/__init__.py", line 413, in execute
    self.fetch_command(subcommand).run_from_argv(self.argv)
  File "/home/user/venv/lib/python3.12/site-packages/django/core/management/base.py", line 354, in run_from_argv
    self.execute(*args, **cmd_options)
  File "/home/user/venv/lib/python3.12/site-packages/django/core/management/base.py", line 398, in execute
    output = self.handle(*args, **options)
  File "/home/user/venv/lib/python3.12/site-packages/django_q/management/commands/qcluster.py", line 22, in handle
    q.start()
  File "/home/user/venv/lib/python3.12/site-packages/django_q/cluster.py", line 78, in start
    self.sentinel.start()
  File "/usr/lib/python3.12/multiprocessing/process.py", line 121, in start
    self._popen = self._Popen(self)
  File "/usr/lib/python3.12/multiprocessing/context.py", line 224, in _Popen
    return _default_context.get_context().Process._Popen(process_obj)
  File "/usr/lib/python3.12/multiprocessing/context.py", line 282, in _Popen
    return Popen(process_obj)
  File "/usr/lib/python3.12/multiprocessing/popen_fork.py", line 19, in __init__
    self._launch(process_obj)
  File "/usr/lib/python3.12/multiprocessing/popen_fork.py", line 71, in _launch
    code = process_obj._bootstrap(parent_sentinel=child_r)
  File "/usr/lib/python3.12/multiprocessing/process.py", line 314, in _bootstrap
    self.run()
  File "/usr/lib/python3.12/multiprocessing/process.py", line 108, in run
    self._target(*self._args, **self._kwargs)
  File "/home/user/venv/lib/python3.12/site-packages/django_q/cluster.py", line 168, in __init__
    self.start()
  File "/home/user/venv/lib/python3.12/site-packages/django_q/cluster.py", line 173, in start
    self.guard()
  File "/home/user/venv/lib/python3.12/site-packages/django_q/cluster.py", line 281, in guard
    self.reincarnate(self.pusher)
  File "/home/user/venv/lib/python3.12/site-packages/django_q/cluster.py", line 222, in reincarnate
    self.pusher = self.spawn_pusher()
  File "/home/user/venv/lib/python3.12/site-packages/django_q/cluster.py", line 201, in spawn_pusher
    return self.spawn_process(pusher, self.task_queue, self.event_out, self.broker)
  File "/home/user/venv/lib/python3.12/site-packages/django_q/cluster.py", line 197, in spawn_process
    p.start()
  File "/usr/lib/python3.12/multiprocessing/process.py", line 121, in start
    self._popen = self._Popen(self)
  File "/usr/lib/python3.12/multiprocessing/context.py", line 224, in _Popen
    return _default_context.get_context().Process._Popen(process_obj)
  File "/usr/lib/python3.12/multiprocessing/context.py", line 282, in _Popen
    return Popen(process_obj)
  File "/usr/lib/python3.12/multiprocessing/popen_fork.py", line 19, in __init__
    self._launch(process_obj)
  File "/usr/lib/python3.12/multiprocessing/popen_fork.py", line 71, in _launch
    code = process_obj._bootstrap(parent_sentinel=child_r)
  File "/usr/lib/python3.12/multiprocessing/process.py", line 314, in _bootstrap
    self.run()
  File "/usr/lib/python3.12/multiprocessing/process.py", line 108, in run
    self._target(*self._args, **self._kwargs)
  File "/home/user/venv/lib/python3.12/site-packages/django_q/cluster.py", line 347, in pusher
    logger.error(e, traceback.format_exc())
Message: ResponseError('UNBLOCKED force unblock from blocking operation, instance state changed (master -> replica?)')
Arguments: ('Traceback (most recent call last):\n  File "/home/user/venv/lib/python3.12/site-packages/django_q/cluster.py", line 345, in pusher\n    task_set = broker.dequeue()\n               ^^^^^^^^^^^^^^^^\n  File "/home/user/venv/lib/python3.12/site-packages/django_q/brokers/redis_broker.py", line 21, in dequeue\n    task = self.connection.blpop(self.list_key, 1)\n           ^^^^^^^^^^^^^^^^^^^^^^^^^^^^^^^^^^^^^^^\n  File "/home/user/venv/lib/python3.12/site-packages/redis/client.py", line 1900, in blpop\n    return self.execute_command(\'BLPOP\', *keys)\n           ^^^^^^^^^^^^^^^^^^^^^^^^^^^^^^^^^^^^\n  File "/home/user/venv/lib/python3.12/site-packages/redis/client.py", line 901, in execute_command\n    return self.parse_response(conn, command_name, **options)\n           ^^^^^^^^^^^^^^^^^^^^^^^^^^^^^^^^^^^^^^^^^^^^^^^^^^\n  File "/home/user/venv/lib/python3.12/site-packages/redis/client.py", line 915, in parse_response\n    response = connection.read_response()\n               ^^^^^^^^^^^^^^^^^^^^^^^^^^\n  File "/home/user/venv/lib/python3.12/site-packages/redis/connection.py", line 756, in read_response\n    raise response\nredis.exceptions.ResponseError: UNBLOCKED force unblock from blocking operation, instance state changed (master -> replica?)\n',)
18:42:52 [Q] INFO Process-1:5 stopped pushing tasks
18:42:52 [Q] ERROR reincarnated pusher Process-1:5 after sudden death
18:42:52 [Q] INFO Process-1:6 pushing tasks at 27258
[01/Jan/2025 21:09:44] code 400, message Bad request syntax ('MGLNDD_83.69.135.57_8000')
[01/Jan/2025 21:09:44] "MGLNDD_83.69.135.57_8000" 400 -
[01/Jan/2025 22:19:57] "GET /admin/ HTTP/1.1" 200 7362
[01/Jan/2025 22:19:57] "GET /favicon.ico HTTP/1.1" 404 179
[01/Jan/2025 22:19:59] "GET /admin/bot_notifier/sentence/ HTTP/1.1" 200 7782
[01/Jan/2025 22:19:59] "GET /admin/jsi18n/ HTTP/1.1" 200 3325
[01/Jan/2025 22:20:03] "GET /admin/bot_notifier/sentence/1/change/ HTTP/1.1" 200 9387
[01/Jan/2025 22:20:03] "GET /admin/jsi18n/ HTTP/1.1" 200 3325
[01/Jan/2025 22:20:07] "GET /admin/bot_notifier/sentence/ HTTP/1.1" 200 7782
[01/Jan/2025 22:20:08] "GET /admin/ HTTP/1.1" 200 7362
[01/Jan/2025 22:20:09] "GET /admin/django_q/schedule/ HTTP/1.1" 200 12073
[01/Jan/2025 22:20:09] "GET /admin/jsi18n/ HTTP/1.1" 200 3325
[01/Jan/2025 22:20:09] "GET /static/admin/img/search.7cf54ff789c6.svg HTTP/1.1" 200 264
[01/Jan/2025 22:20:09] "GET /static/admin/img/sorting-icons.3a097b59f104.svg HTTP/1.1" 200 366
[01/Jan/2025 22:20:16] "GET /admin/django_q/schedule/1/change/ HTTP/1.1" 200 13782
[01/Jan/2025 22:20:16] "GET /admin/jsi18n/ HTTP/1.1" 200 3325
[01/Jan/2025 22:20:37] "GET /admin/django_q/schedule/1/change/ HTTP/1.1" 200 13782
[01/Jan/2025 22:20:37] "GET /admin/jsi18n/ HTTP/1.1" 200 3325
[01/Jan/2025 22:20:53] "POST /admin/django_q/schedule/1/change/ HTTP/1.1" 302 0
[01/Jan/2025 22:20:53] "GET /admin/django_q/schedule/1/change/ HTTP/1.1" 200 14065
[01/Jan/2025 22:20:53] "GET /admin/jsi18n/ HTTP/1.1" 200 3325
[01/Jan/2025 22:20:57] "GET /admin/ HTTP/1.1" 200 7703
[01/Jan/2025 22:20:58] "GET /admin/bot_notifier/sentence/ HTTP/1.1" 200 7782
[01/Jan/2025 22:20:58] "GET /admin/jsi18n/ HTTP/1.1" 200 3325
[01/Jan/2025 22:21:00] "GET /admin/ HTTP/1.1" 200 7703
[01/Jan/2025 22:21:01] "GET /admin/bot_notifier/botuser/ HTTP/1.1" 200 8129
[01/Jan/2025 22:21:01] "GET /admin/jsi18n/ HTTP/1.1" 200 3325
[01/Jan/2025 22:21:05] "GET /admin/bot_notifier/ HTTP/1.1" 200 3332
[01/Jan/2025 22:21:06] "GET /admin/bot_notifier/sentence/ HTTP/1.1" 200 7782
[01/Jan/2025 22:21:07] "GET /admin/jsi18n/ HTTP/1.1" 200 3325
[01/Jan/2025 22:21:08] "GET /admin/bot_notifier/sentence/1/change/ HTTP/1.1" 200 9387
[01/Jan/2025 22:21:08] "GET /admin/jsi18n/ HTTP/1.1" 200 3325
[01/Jan/2025 22:24:19] "POST /admin/bot_notifier/sentence/1/change/ HTTP/1.1" 302 0
[01/Jan/2025 22:24:20] "GET /admin/bot_notifier/sentence/1/change/ HTTP/1.1" 200 10267
[01/Jan/2025 22:24:20] "GET /admin/jsi18n/ HTTP/1.1" 200 3325
[01/Jan/2025 22:27:08] "GET /admin/ HTTP/1.1" 200 8214
[01/Jan/2025 22:27:10] "GET /admin/django_q/schedule/ HTTP/1.1" 200 12069
[01/Jan/2025 22:27:10] "GET /admin/jsi18n/ HTTP/1.1" 200 3325
[01/Jan/2025 22:27:11] "GET /admin/django_q/schedule/1/change/ HTTP/1.1" 200 13782
[01/Jan/2025 22:27:11] "GET /admin/jsi18n/ HTTP/1.1" 200 3325
[01/Jan/2025 22:27:14] "GET /admin/django_q/schedule/ HTTP/1.1" 200 12069
[01/Jan/2025 22:27:16] "GET /admin/django_q/schedule/1/change/ HTTP/1.1" 200 13782
[01/Jan/2025 22:27:16] "GET /admin/jsi18n/ HTTP/1.1" 200 3325
[01/Jan/2025 22:44:11] "GET / HTTP/1.1" 404 179
[01/Jan/2025 23:01:14] "GET / HTTP/1.1" 404 179
[02/Jan/2025 00:41:43] "CONNECT example.com:443 HTTP/1.1" 404 179
[02/Jan/2025 05:37:13] code 400, message Bad request version ('À\x14À')
[02/Jan/2025 05:37:13] You're accessing the development server over HTTPS, but it only supports HTTP.

[02/Jan/2025 05:37:24] code 400, message Bad request syntax ('SSH-2.0-Go')
[02/Jan/2025 05:37:24] "SSH-2.0-Go" 400 -
07:00:20 [Q] INFO Enqueued 1
07:00:20 [Q] INFO Process-1 created a task from schedule [sent nimadur]
07:00:20 [Q] INFO Process-1:1 processing [east-december-avocado-spring]
07:00:22 [Q] INFO Processed [east-december-avocado-spring]
[02/Jan/2025 07:04:53] "GET /.env HTTP/1.1" 200 212
--- Logging error ---
Traceback (most recent call last):
  File "/home/user/venv/lib/python3.12/site-packages/django_q/cluster.py", line 345, in pusher
    task_set = broker.dequeue()
               ^^^^^^^^^^^^^^^^
  File "/home/user/venv/lib/python3.12/site-packages/django_q/brokers/redis_broker.py", line 21, in dequeue
    task = self.connection.blpop(self.list_key, 1)
           ^^^^^^^^^^^^^^^^^^^^^^^^^^^^^^^^^^^^^^^
  File "/home/user/venv/lib/python3.12/site-packages/redis/client.py", line 1900, in blpop
    return self.execute_command('BLPOP', *keys)
           ^^^^^^^^^^^^^^^^^^^^^^^^^^^^^^^^^^^^
  File "/home/user/venv/lib/python3.12/site-packages/redis/client.py", line 901, in execute_command
    return self.parse_response(conn, command_name, **options)
           ^^^^^^^^^^^^^^^^^^^^^^^^^^^^^^^^^^^^^^^^^^^^^^^^^^
  File "/home/user/venv/lib/python3.12/site-packages/redis/client.py", line 915, in parse_response
    response = connection.read_response()
               ^^^^^^^^^^^^^^^^^^^^^^^^^^
  File "/home/user/venv/lib/python3.12/site-packages/redis/connection.py", line 756, in read_response
    raise response
redis.exceptions.ResponseError: UNBLOCKED force unblock from blocking operation, instance state changed (master -> replica?)

During handling of the above exception, another exception occurred:

Traceback (most recent call last):
  File "/usr/lib/python3.12/logging/__init__.py", line 1160, in emit
    msg = self.format(record)
          ^^^^^^^^^^^^^^^^^^^
  File "/usr/lib/python3.12/logging/__init__.py", line 999, in format
    return fmt.format(record)
           ^^^^^^^^^^^^^^^^^^
  File "/usr/lib/python3.12/logging/__init__.py", line 703, in format
    record.message = record.getMessage()
                     ^^^^^^^^^^^^^^^^^^^
  File "/usr/lib/python3.12/logging/__init__.py", line 392, in getMessage
    msg = msg % self.args
          ~~~~^~~~~~~~~~~
TypeError: not all arguments converted during string formatting
Call stack:
  File "/home/user/KepfutsiyBot/manage.py", line 22, in <module>
    main()
  File "/home/user/KepfutsiyBot/manage.py", line 18, in main
    execute_from_command_line(sys.argv)
  File "/home/user/venv/lib/python3.12/site-packages/django/core/management/__init__.py", line 419, in execute_from_command_line
    utility.execute()
  File "/home/user/venv/lib/python3.12/site-packages/django/core/management/__init__.py", line 413, in execute
    self.fetch_command(subcommand).run_from_argv(self.argv)
  File "/home/user/venv/lib/python3.12/site-packages/django/core/management/base.py", line 354, in run_from_argv
    self.execute(*args, **cmd_options)
  File "/home/user/venv/lib/python3.12/site-packages/django/core/management/base.py", line 398, in execute
    output = self.handle(*args, **options)
  File "/home/user/venv/lib/python3.12/site-packages/django_q/management/commands/qcluster.py", line 22, in handle
    q.start()
  File "/home/user/venv/lib/python3.12/site-packages/django_q/cluster.py", line 78, in start
    self.sentinel.start()
  File "/usr/lib/python3.12/multiprocessing/process.py", line 121, in start
    self._popen = self._Popen(self)
  File "/usr/lib/python3.12/multiprocessing/context.py", line 224, in _Popen
    return _default_context.get_context().Process._Popen(process_obj)
  File "/usr/lib/python3.12/multiprocessing/context.py", line 282, in _Popen
    return Popen(process_obj)
  File "/usr/lib/python3.12/multiprocessing/popen_fork.py", line 19, in __init__
    self._launch(process_obj)
  File "/usr/lib/python3.12/multiprocessing/popen_fork.py", line 71, in _launch
    code = process_obj._bootstrap(parent_sentinel=child_r)
  File "/usr/lib/python3.12/multiprocessing/process.py", line 314, in _bootstrap
    self.run()
  File "/usr/lib/python3.12/multiprocessing/process.py", line 108, in run
    self._target(*self._args, **self._kwargs)
  File "/home/user/venv/lib/python3.12/site-packages/django_q/cluster.py", line 168, in __init__
    self.start()
  File "/home/user/venv/lib/python3.12/site-packages/django_q/cluster.py", line 173, in start
    self.guard()
  File "/home/user/venv/lib/python3.12/site-packages/django_q/cluster.py", line 281, in guard
    self.reincarnate(self.pusher)
  File "/home/user/venv/lib/python3.12/site-packages/django_q/cluster.py", line 222, in reincarnate
    self.pusher = self.spawn_pusher()
  File "/home/user/venv/lib/python3.12/site-packages/django_q/cluster.py", line 201, in spawn_pusher
    return self.spawn_process(pusher, self.task_queue, self.event_out, self.broker)
  File "/home/user/venv/lib/python3.12/site-packages/django_q/cluster.py", line 197, in spawn_process
    p.start()
  File "/usr/lib/python3.12/multiprocessing/process.py", line 121, in start
    self._popen = self._Popen(self)
  File "/usr/lib/python3.12/multiprocessing/context.py", line 224, in _Popen
    return _default_context.get_context().Process._Popen(process_obj)
  File "/usr/lib/python3.12/multiprocessing/context.py", line 282, in _Popen
    return Popen(process_obj)
  File "/usr/lib/python3.12/multiprocessing/popen_fork.py", line 19, in __init__
    self._launch(process_obj)
  File "/usr/lib/python3.12/multiprocessing/popen_fork.py", line 71, in _launch
    code = process_obj._bootstrap(parent_sentinel=child_r)
  File "/usr/lib/python3.12/multiprocessing/process.py", line 314, in _bootstrap
    self.run()
  File "/usr/lib/python3.12/multiprocessing/process.py", line 108, in run
    self._target(*self._args, **self._kwargs)
  File "/home/user/venv/lib/python3.12/site-packages/django_q/cluster.py", line 347, in pusher
    logger.error(e, traceback.format_exc())
Message: ResponseError('UNBLOCKED force unblock from blocking operation, instance state changed (master -> replica?)')
Arguments: ('Traceback (most recent call last):\n  File "/home/user/venv/lib/python3.12/site-packages/django_q/cluster.py", line 345, in pusher\n    task_set = broker.dequeue()\n               ^^^^^^^^^^^^^^^^\n  File "/home/user/venv/lib/python3.12/site-packages/django_q/brokers/redis_broker.py", line 21, in dequeue\n    task = self.connection.blpop(self.list_key, 1)\n           ^^^^^^^^^^^^^^^^^^^^^^^^^^^^^^^^^^^^^^^\n  File "/home/user/venv/lib/python3.12/site-packages/redis/client.py", line 1900, in blpop\n    return self.execute_command(\'BLPOP\', *keys)\n           ^^^^^^^^^^^^^^^^^^^^^^^^^^^^^^^^^^^^\n  File "/home/user/venv/lib/python3.12/site-packages/redis/client.py", line 901, in execute_command\n    return self.parse_response(conn, command_name, **options)\n           ^^^^^^^^^^^^^^^^^^^^^^^^^^^^^^^^^^^^^^^^^^^^^^^^^^\n  File "/home/user/venv/lib/python3.12/site-packages/redis/client.py", line 915, in parse_response\n    response = connection.read_response()\n               ^^^^^^^^^^^^^^^^^^^^^^^^^^\n  File "/home/user/venv/lib/python3.12/site-packages/redis/connection.py", line 756, in read_response\n    raise response\nredis.exceptions.ResponseError: UNBLOCKED force unblock from blocking operation, instance state changed (master -> replica?)\n',)
07:05:06 [Q] INFO Process-1:6 stopped pushing tasks
07:05:06 [Q] ERROR reincarnated pusher Process-1:6 after sudden death
07:05:06 [Q] INFO Process-1:7 pushing tasks at 34456
[02/Jan/2025 09:32:55,689] - Broken pipe from ('167.94.146.57', 33792)

[02/Jan/2025 09:32:58] "GET / HTTP/1.1" 404 179
[02/Jan/2025 09:33:04,773] - Broken pipe from ('167.94.146.57', 33892)

[02/Jan/2025 09:33:08] "GET / HTTP/1.1" 404 179
[02/Jan/2025 09:33:08] code 505, message Invalid HTTP version (2.0)
[02/Jan/2025 09:33:08] "PRI * HTTP/2.0" 505 -
[02/Jan/2025 11:40:40,715] - Broken pipe from ('206.168.34.197', 46998)

[02/Jan/2025 11:40:44] "GET / HTTP/1.1" 404 179
[02/Jan/2025 11:40:50,865] - Broken pipe from ('206.168.34.197', 47002)

[02/Jan/2025 11:40:55] "GET / HTTP/1.1" 404 179
[02/Jan/2025 11:40:56] code 505, message Invalid HTTP version (2.0)
[02/Jan/2025 11:40:56] "PRI * HTTP/2.0" 505 -
